Workbook

Sheet Task 1 - Bubble Sort
B2: Detecting Models
B3: ChatGPT-4o | F3: Gemini 2.5 Pro | J3: Claude Sonnet 4 | N3: Mistral Le Chat | R3: Perplexity | V3: DeepSeek V3 | Z3: Llama-4-Scout-nitro | AD3: Grok-3 | AH3: Qwen3-235b-a22b | AL3: Falcon-H1-3B-Instruct
A4: Generating Models | B4: Min Percent | C4: Max Percent | D4: Avg. Percent | E4: Suggested Models | F4: Min Percent | G4: Max Percent | H4: Avg. Percent | I4: Suggested Models | J4: Min Percent | K4: Max Percent | L4: Avg. Percent | M4: Suggested Models | N4: Min Percent | O4: Max Percent | P4: Avg. Percent | Q4: Suggested Models | R4: Min Percent | S4: Max Percent | T4: Avg. Percent | U4: Suggested Models | V4: Min Percent | W4: Max Percent | X4: Avg. Percent | Y4: Suggested Models | Z4: Min Percent | AA4: Max Percent | AB4: Avg. Percent | AC4: Suggested Models | AD4: Min Percent | AE4: Max Percent | AF4: Avg. Percent | AG4: Suggested Models | AH4: Min Percent | AI4: Max Percent | AJ4: Avg. Percent | AK4: Suggested Models | AL4: Min Percent | AM4: Max Percent | AN4: Avg. Percent | AO4: Suggested Models | AR4: Model | AS4: Ability to detect | AT4: Ability to be detected
A5: ChatGPT-4o | B5: 90 | C5: 95 | D5: =AVERAGE(B5:C5) -> 92.5 | E5: GPT-4, GPT-4o, GitHub Copilot, Gemini | H5: 100 | I5: Gemini, GPT-4 and later, Claude 3 | J5: 95 | K5: 98 | L5: =AVERAGE(J5:K5) -> 96.5 | M5: GPT-3.5 or GPT-4 | Q5: GPT-3 or GPT-4 | R5: 90 | S5: 100 | T5: 95 | U5: GPT-3.5 or GPT-4 | X5: 100 | Y5: GPT-4 | AB5: 80 | AC5: GPT-3 | AF5: 100 | AG5: GPT-4 or earlier or Grok (xAI) | AJ5: 100 | AK5: GPT-3.5 or GPT-4 | AN5: 0 | AO5: NA | AR5: ChatGPT-4o | AS5: 98.1 | AT5: =AVERAGE(D5,H5,L5,T5,X5,AB5,AF5,AJ5,AN5) -> 84.888889
A6: Gemini 2.5 Pro | B6: 98 | C6: 100 | D6: =AVERAGE(B6:C6) -> 99 | E6: GPT-4 or GPT-4o | H6: 100 | I6: Gemini, SGE | J6: 90 | K6: 95 | L6: =AVERAGE(J6:K6) -> 92.5 | M6: GPT-4 or Claude | Q6: GPT-3 or GPT-4 | R6: 90 | S6: 100 | T6: 95 | U6: GPT-3.5 or GPT-4 | V6: 80 | W6: 90 | X6: 85 | Y6: GPT-4 | AB6: 90 | AC6: GPT-3, LLaMA | AF6: 100 | AG6: GPT-4 or earlier or Grok (xAI) | AJ6: 100 | AK6: GPT-3.5 or GPT-4 | AN6: 0 | AO6: NA | AR6: Gemini 2.5 Pro | AS6: 90 | AT6: =AVERAGE(D6,H6,L6,T6,X6,AB6,AF6,AJ6,AN6) -> 84.611111
A7: Claude Sonnet 4 | B7: 98 | C7: 100 | D7: =AVERAGE(B7:C7) -> 99 | E7: GPT-4 or GPT-4o | H7: 100 | I7: Gemini, GPT-4 and later, Claude 3 | J7: 15 | K7: 25 | L7: =AVERAGE(J7:K7) -> 20 | M7: GPT-4 | Q7: GPT-3 or GPT-4 | R7: 90 | S7: 100 | T7: 95 | U7: GPT-3.5 or GPT-4 | X7: 100 | Y7: GPT-4 | AB7: 85 | AC7: GPT-3, LLaMA | AF7: 100 | AG7: GPT-4 or earlier or Grok (xAI) | AJ7: 100 | AK7: GPT-3.5 or GPT-4 | AN7: 0 | AO7: NA | AR7: Claude Sonnet 4 | AS7: 77.05 | AT7: =AVERAGE(D7,H7,L7,T7,X7,AB7,AF7,AJ7,AN7) -> 77.666667
A8: Mistral Le Chat | B8: 98 | C8: 100 | D8: =AVERAGE(B8:C8) -> 99 | E8: GPT-4 or GPT-4o | H8: 100 | I8: Gemini, GPT-4 and later, Claude 3 | J8: 85 | K8: 90 | L8: =AVERAGE(J8:K8) -> 87.5 | M8: GPT-3.5 or GPT-4 | Q8: GPT-3 or GPT-4 | R8: 90 | S8: 100 | T8: 95 | U8: GPT-3.5 or GPT-4 | X8: 100 | Y8: GPT-4 | AB8: 95 | AC8: GPT-3, LLaMA | AF8: 100 | AG8: GPT-4 or earlier or Grok (xAI) | AH8: 85 | AI8: 90 | AJ8: =AVERAGE(AH8:AI8) -> 87.5 | AK8: GPT-3.5 or GPT-4 | AN8: 0 | AO8: NA | AR8: Mistral Le Chat | AT8: =AVERAGE(D8,H8,L8,T8,X8,AB8,AF8,AJ8,AN8) -> 84.888889
A9: Perplexity | B9: 95 | C9: 98 | D9: =AVERAGE(B9:C9) -> 96.5 | E9: GPT-4 or GPT-4o | H9: 100 | I9: Gemini, GPT-4 and later, Claude 3 | J9: 90 | K9: 95 | L9: =AVERAGE(J9:K9) -> 92.5 | M9: GPT-3.5 or GPT-4 | Q9: GPT-3 or GPT-4 | R9: 90 | S9: 100 | T9: 95 | U9: GPT-3.5 or GPT-4 | V9: 70 | W9: 80 | X9: 75 | Y9: GPT-4 | AB9: 90 | AC9: GPT-3, LLaMA | AF9: 100 | AG9: GPT-4 or earlier or Grok (xAI) | AH9: 90 | AI9: 95 | AJ9: =AVERAGE(AH9:AI9) -> 92.5 | AK9: GPT-3.5 or GPT-4 | AL9: 70 | AM9: 80 | AN9: =AVERAGE(AL9:AM9) -> 75 | AO9: GPT-3 or GPT-4 | AR9: Perplexity | AS9: 95 | AT9: =AVERAGE(D9,H9,L9,T9,X9,AB9,AF9,AJ9,AN9) -> 90.722222
A10: DeepSeek V3 | B10: 99 | C10: 100 | D10: =AVERAGE(B10:C10) -> 99.5 | E10: GPT-4 or GPT-4o | F10: 90 | G10: 100 | H10: =AVERAGE(F10:G10) -> 95 | I10: GPT-3.5, GPT-4, Gemini | J10: 90 | K10: 95 | L10: =AVERAGE(J10:K10) -> 92.5 | M10: GPT-4 | Q10: GPT-3 or GPT-4 | R10: 90 | S10: 100 | T10: 95 | U10: GPT-3.5 or GPT-4 | X10: 100 | Y10: GPT-3 or GPT-4 | AB10: 95 | AC10: GPT-3, LLaMA | AF10: 100 | AG10: GPT-4 or earlier or Grok (xAI) | AH10: 80 | AI10: 90 | AJ10: =AVERAGE(AH10:AI10) -> 85 | AK10: GPT-3, GPT-3.5, Llama 2, Llama 3 | AL10: 20 | AM10: 30 | AN10: =AVERAGE(AL10:AM10) -> 25 | AO10: GPT-3 or GPT-4 | AR10: DeepSeek V3 | AS10: 96 | AT10: =AVERAGE(D10,H10,L10,T10,X10,AB10,AF10,AJ10,AN10) -> 87.444444
A11: Llama-4-Scout-nitro | B11: 99 | C11: 100 | D11: =AVERAGE(B11:C11) -> 99.5 | E11: GPT-4 or GPT-4o | F11: 95 | G11: 100 | H11: =AVERAGE(F11:G11) -> 97.5 | I11: GPT-3.5, GPT-4, Gemini | J11: 95 | K11: 98 | L11: =AVERAGE(J11:K11) -> 96.5 | M11: GPT-4 | Q11: GPT-3 or GPT-4 | R11: 90 | S11: 100 | T11: 95 | U11: GPT-3.5 or GPT-4 | X11: 100 | Y11: GPT-3 or GPT-4 | AB11: 98 | AC11: GPT-3, LLaMA | AF11: 100 | AG11: GPT-4 or earlier or Grok (xAI) | AH11: 95 | AI11: 100 | AJ11: =AVERAGE(AH11:AI11) -> 97.5 | AK11: GPT-3, GPT-3.5, Llama 2/3, Claude 2/3 | AL11: 10 | AM11: 20 | AN11: =AVERAGE(AL11:AM11) -> 15 | AO11: GPT-3 or GPT-4 | AR11: Llama-4-Scout-nitro | AS11: 91 | AT11: =AVERAGE(D11,H11,L11,T11,X11,AB11,AF11,AJ11,AN11) -> 88.777778
A12: Grok-3 | B12: 95 | C12: 100 | D12: =AVERAGE(B12:C12) -> 97.5 | E12: GPT-4 or GPT-4o | F12: 10 | G12: 30 | H12: =AVERAGE(F12:G12) -> 20 | I12: GPT-4 or Gemini | J12: 10 | K12: 15 | L12: =AVERAGE(J12:K12) -> 12.5 | M12: NA | Q12: GPT-3 or GPT-4 | R12: 90 | S12: 100 | T12: 95 | U12: GPT-3.5 or GPT-4, Claude | X12: 100 | Y12: GPT-3 or GPT-4 | AB12: 90 | AC12: GPT-3, LLaMA | AF12: 80 | AG12: GPT-4 or earlier or Grok (xAI) | AH12: 95 | AI12: 100 | AJ12: =AVERAGE(AH12:AI12) -> 97.5 | AK12: GPT-3, GPT-3.5, Llama 2/3, Claude 2/3 | AL12: 10 | AM12: 15 | AN12: =AVERAGE(AL12:AM12) -> 12.5 | AO12: GPT-3 or GPT-4 | AR12: Grok-3 | AS12: 96 | AT12: =AVERAGE(D12,H12,L12,T12,X12,AB12,AF12,AJ12,AN12) -> 67.222222
A13: Qwen3-235b-a22b | B13: 99 | C13: 100 | D13: =AVERAGE(B13:C13) -> 99.5 | E13: GPT-4 or GPT-4o | F13: 95 | G13: 100 | H13: =AVERAGE(F13:G13) -> 97.5 | I13: GPT-3.5, GPT-4, Gemini | J13: 90 | K13: 95 | L13: =AVERAGE(J13:K13) -> 92.5 | M13: GPT-4 | Q13: GPT-3 or GPT-4 | R13: 90 | S13: 100 | T13: 95 | U13: GPT-3.5 or GPT-4, Claude | X13: 100 | Y13: GPT-3 or GPT-4 | AB13: 95 | AC13: GPT-3, LLaMA | AF13: 100 | AG13: GPT-4 or earlier or Grok (xAI) | AH13: 95 | AI13: 100 | AJ13: =AVERAGE(AH13:AI13) -> 97.5 | AK13: GPT-3.5, GPT-4, Llama 3, or Claude 3 | AL13: 5 | AM13: 10 | AN13: =AVERAGE(AL13:AM13) -> 7.5 | AO13: GPT-3 or GPT-4 | AR13: Qwen3-235b-a22b | AS13: 95.5 | AT13: =AVERAGE(D13,H13,L13,T13,X13,AB13,AF13,AJ13,AN13) -> 87.166667
A14: Falcon-H1-3B-Instruct | B14: 98 | C14: 100 | D14: =AVERAGE(B14:C14) -> 99 | E14: GPT-4 or GPT-4o | F14: 85 | G14: 95 | H14: =AVERAGE(F14:G14) -> 90 | I14: Gemini, GPT-4 and later, Claude 3 | J14: 85 | K14: 90 | L14: =AVERAGE(J14:K14) -> 87.5 | M14: GPT-3.5 or GPT-4 | Q14: GPT-3 or GPT-4 | R14: 90 | S14: 100 | T14: 95 | U14: GPT-3.5 or GPT-4, Claude | X14: 100 | Y14: GPT-3 or GPT-4 | AB14: 92 | AC14: GPT-3, LLaMA | AF14: 80 | AG14: GPT-4 or earlier or Grok (xAI) | AH14: 95 | AI14: 100 | AJ14: =AVERAGE(AH14:AI14) -> 97.5 | AK14: GPT-3.5, GPT-4, Llama 3, or Claude 3 | AL14: 5 | AM14: 10 | AN14: =AVERAGE(AL14:AM14) -> 7.5 | AO14: GPT-3 or GPT-4 | AR14: Falcon-H1-3B-Instruct | AS14: 14.25 | AT14: =AVERAGE(D14,H14,L14,T14,X14,AB14,AF14,AJ14,AN14) -> 83.166667
A15: Mean | D15: =AVERAGE(D5:D14) -> 98.1 | H15: =AVERAGE(H5:H14) -> 90 | L15: =AVERAGE(L5:L14) -> 77.05 | T15: =AVERAGE(T5:T14) -> 95 | X15: =AVERAGE(X5:X14) -> 96 | AB15: =AVERAGE(AB5:AB14) -> 91 | AF15: =AVERAGE(AF5:AF14) -> 96 | AJ15: =AVERAGE(AJ5:AJ14) -> 95.5 | AN15: =AVERAGE(AN5:AN14) -> 14.25
AR25: Model | AS25: Ability to detect
AR26: Falcon-H1-3B-Instruct | AS26: 14.25
AR27: Claude Sonnet 4 | AS27: 77.05
AR28: Gemini 2.5 Pro | AS28: 90
AR29: Llama-4-Scout-nitro | AS29: 91
AR30: Perplexity | AS30: 95
AR31: Qwen3-235b-a22b | AS31: 95.5
AR32: DeepSeek V3 | AS32: 96
AR33: Grok-3 | AS33: 96
AR34: ChatGPT-4o | AS34: 98.1
AR35: Mistral Le Chat
AR39: Model | AS39: Ability to be detected
AR40: Grok-3 | AS40: 67.222222
AR41: Claude Sonnet 4 | AS41: 77.666667
AR42: Falcon-H1-3B-Instruct | AS42: 83.166667
AR43: Gemini 2.5 Pro | AS43: 84.611111
AR44: ChatGPT-4o | AS44: 84.888889
AR45: Mistral Le Chat | AS45: 84.888889
AR46: Qwen3-235b-a22b | AS46: 87.166667
AR47: DeepSeek V3 | AS47: 87.444444
AR48: Llama-4-Scout-nitro | AS48: 88.777778
AR49: Perplexity | AS49: 90.722222

Sheet Task 2 - CLA
B2: Detecting Models
B3: ChatGPT-4o | F3: Gemini 2.5 Pro | J3: Claude Sonnet 4 | N3: Mistral Le Chat | R3: Perplexity | V3: DeepSeek V3 | Z3: Llama-4-Scout-nitro | AD3: Grok-3 | AH3: Qwen3-235b-a22b | AL3: Falcon-H1-3B-Instruct
A4: Generating Models | B4: Min Percent | C4: Max Percent | D4: Avg. Percent | E4: Suggested Models | F4: Min Percent | G4: Max Percent | H4: Avg. Percent | I4: Suggested Models | J4: Min Percent | K4: Max Percent | L4: Avg. Percent | M4: Suggested Models | N4: Min Percent | O4: Max Percent | P4: Avg. Percent | Q4: Suggested Models | R4: Min Percent | S4: Max Percent | T4: Avg. Percent | U4: Suggested Models | V4: Min Percent | W4: Max Percent | X4: Avg. Percent | Y4: Suggested Models | Z4: Min Percent | AA4: Max Percent | AB4: Avg. Percent | AC4: Suggested Models | AD4: Min Percent | AE4: Max Percent | AF4: Avg. Percent | AG4: Suggested Models | AH4: Min Percent | AI4: Max Percent | AJ4: Avg. Percent | AK4: Suggested Models | AL4: Min Percent | AM4: Max Percent | AN4: Avg. Percent | AO4: Suggested Models | AR4: Model | AS4: Ability to detect | AT4: Ability to be detected
A5: ChatGPT-4o | B5: 90 | C5: 95 | D5: =AVERAGE(B5:C5) -> 92.5 | E5: GPT-4, GPT-4o, Claude 3, Gemini 1.5 | H5: 100 | I5: GPT-3.5, GPT-4, PaLM 2, Gemini | J5: 85 | K5: 90 | L5: =AVERAGE(J5:K5) -> 87.5 | M5: GPT-3.5, GPT-4 | Q5: GPT-4 | T5: 70 | U5: GPT-3, GPT-4, Claude | X5: 100 | Y5: GPT-4 | AB5: 30 | AC5: LLaMA, BLOOM | AD5: 70 | AE5: 80 | AF5: =AVERAGE(AD5:AE5) -> 75 | AG5: Claude, GPT-4 | AH5: 95 | AI5: 100 | AJ5: =AVERAGE(AH5:AI5) -> 97.5 | AK5: GPT-3.5, GPT-4, Llama 3, Claude 3 | AN5: 0 | AO5: NA | AR5: ChatGPT-4o | AS5: =D15 -> 96.5 | AT5: =AVERAGE(D5,H5,L5,T5,X5,AB5,AF5,AJ5,AN5) -> 72.5
A6: Gemini 2.5 Pro | B6: 95 | C6: 100 | D6: =AVERAGE(B6:C6) -> 97.5 | E6: GPT-4, Claude 3, Gemini 1.5 | H6: 100 | I6: GPT-4, Gemini | J6: 95 | K6: 98 | L6: =AVERAGE(J6:K6) -> 96.5 | M6: Perplexity AI | Q6: GPT-4 | T6: 50 | U6: GPT-3.5, GPT-4 | X6: 100 | Y6: GPT-4 | AB6: 60 | AC6: T5, BART | AD6: 80 | AE6: 90 | AF6: =AVERAGE(AD6:AE6) -> 85 | AG6: Claude, GPT-4 | AH6: 95 | AI6: 100 | AJ6: =AVERAGE(AH6:AI6) -> 97.5 | AK6: GPT-3.5, GPT-4, Llama 3, Claude 3 | AN6: 0 | AO6: NA | AR6: Gemini 2.5 Pro | AS6: =H15 -> 100 | AT6: =AVERAGE(D6,H6,L6,T6,X6,AB6,AF6,AJ6,AN6) -> 76.277778
A7: Claude Sonnet 4 | B7: 95 | C7: 100 | D7: =AVERAGE(B7:C7) -> 97.5 | E7: GPT-4, Claude 3 | H7: 100 | I7: GPT-3.5, GPT-4, Gemini | J7: 90 | K7: 95 | L7: =AVERAGE(J7:K7) -> 92.5 | M7: GPT-4, Claude | Q7: GPT-4 | T7: 65 | U7: GPT-3, GPT-4, Claude, Gemini | X7: 100 | Y7: GPT-4 | AB7: 40 | AC7: LLaMA, T5 | AD7: 60 | AE7: 70 | AF7: =AVERAGE(AD7:AE7) -> 65 | AG7: Claude, GPT-4 | AH7: 95 | AI7: 100 | AJ7: =AVERAGE(AH7:AI7) -> 97.5 | AK7: GPT-3.5, GPT-4, Llama 3, Claude 3 | AN7: 0 | AO7: NA | AR7: Claude Sonnet 4 | AS7: =L15 -> 92.7 | AT7: =AVERAGE(D7,H7,L7,T7,X7,AB7,AF7,AJ7,AN7) -> 73.055556
A8: Mistral Le Chat | B8: 90 | C8: 95 | D8: =AVERAGE(B8:C8) -> 92.5 | E8: GPT-4, Claude 3 | H8: 100 | I8: GPT-4, Gemini | J8: 95 | K8: 98 | L8: =AVERAGE(J8:K8) -> 96.5 | M8: GPT-3.5, GPT-4 | Q8: GPT-4 | T8: 70 | U8: GPT-3, GPT-4, Claude, Gemini | X8: 100 | Y8: GPT-4 | AB8: 80 | AC8: T5, BART | AD8: 65 | AE8: 75 | AF8: =AVERAGE(AD8:AE8) -> 70 | AG8: Claude, GPT-4 | AH8: 95 | AI8: 100 | AJ8: =AVERAGE(AH8:AI8) -> 97.5 | AK8: GPT-3.5, GPT-4, Llama 3, Claude 3 | AN8: 0 | AO8: NA | AR8: Mistral Le Chat | AT8: =AVERAGE(D8,H8,L8,T8,X8,AB8,AF8,AJ8,AN8) -> 78.5
A9: Perplexity | B9: 95 | C9: 100 | D9: =AVERAGE(B9:C9) -> 97.5 | E9: GPT-4 | H9: 100 | I9: GPT-3.5, GPT-4, Gemini | J9: 85 | K9: 90 | L9: =AVERAGE(J9:K9) -> 87.5 | M9: GPT-4, Claude | Q9: GPT-4 | T9: 70 | U9: GPT-3.5, GPT-4 | X9: 100 | Y9: GPT-4 | AB9: 20 | AC9: NA | AD9: 70 | AE9: 80 | AF9: =AVERAGE(AD9:AE9) -> 75 | AG9: Claude, GPT-4 | AH9: 95 | AI9: 100 | AJ9: =AVERAGE(AH9:AI9) -> 97.5 | AK9: GPT-3.5, GPT-4, Llama 3, Claude 3 | AN9: 0 | AO9: NA | AR9: Perplexity | AS9: =T15 -> 68.5 | AT9: =AVERAGE(D9,H9,L9,T9,X9,AB9,AF9,AJ9,AN9) -> 71.944444
A10: DeepSeek V3 | B10: 95 | C10: 100 | D10: =AVERAGE(B10:C10) -> 97.5 | E10: GPT-4 | H10: 100 | I10: GPT-4, Gemini | J10: 95 | K10: 98 | L10: =AVERAGE(J10:K10) -> 96.5 | M10: GPT-4 | Q10: GPT-4 | T10: 70 | U10: GPT-4 | X10: 100 | Y10: GPT-4 | AB10: 90 | AC10: T5, BART | AD10: 80 | AE10: 90 | AF10: =AVERAGE(AD10:AE10) -> 85 | AG10: Claude, GPT-4 | AJ10: 100 | AK10: GPT-4 | AN10: 0 | AO10: NA | AR10: DeepSeek V3 | AS10: =X15 -> 100 | AT10: =AVERAGE(D10,H10,L10,T10,X10,AB10,AF10,AJ10,AN10) -> 82.111111
A11: Llama-4-Scout-nitro | B11: 95 | C11: 100 | D11: =AVERAGE(B11:C11) -> 97.5 | E11: GPT-4 | H11: 100 | I11: GPT-4, Gemini | J11: 90 | K11: 95 | L11: =AVERAGE(J11:K11) -> 92.5 | M11: GPT-4 | Q11: GPT-4 | T11: 70 | U11: GPT-4 | X11: 100 | Y11: GPT-4 | AB11: 70 | AC11: T5, BART | AD11: 90 | AE11: 95 | AF11: =AVERAGE(AD11:AE11) -> 92.5 | AG11: Claude, GPT-4 | AJ11: 100 | AK11: GPT-4 | AN11: 0 | AO11: NA | AR11: Llama-4-Scout-nitro | AS11: =AB15 -> 59 | AT11: =AVERAGE(D11,H11,L11,T11,X11,AB11,AF11,AJ11,AN11) -> 80.277778
A12: Grok-3 | B12: 95 | C12: 100 | D12: =AVERAGE(B12:C12) -> 97.5 | E12: GPT-4 | H12: 100 | I12: GPT-4, Gemini | J12: 85 | K12: 90 | L12: =AVERAGE(J12:K12) -> 87.5 | M12: GPT-4 | Q12: GPT-4 | T12: 70 | U12: GPT-4 | X12: 100 | Y12: GPT-4 | AB12: 30 | AC12: NA | AD12: 75 | AE12: 85 | AF12: =AVERAGE(AD12:AE12) -> 80 | AG12: Claude, GPT-4 | AJ12: 100 | AK12: GPT-4 | AN12: 0 | AO12: NA | AR12: Grok-3 | AS12: =AF15 -> 79.25 | AT12: =AVERAGE(D12,H12,L12,T12,X12,AB12,AF12,AJ12,AN12) -> 73.888889
A13: Qwen3-235b-a22b | B13: 95 | C13: 100 | D13: =AVERAGE(B13:C13) -> 97.5 | E13: GPT-4 | H13: 100 | I13: GPT-4, Gemini | J13: 95 | K13: 98 | L13: =AVERAGE(J13:K13) -> 96.5 | M13: GPT-4 | Q13: GPT-4 | R13: 70 | S13: 80 | T13: =AVERAGE(R13:S13) -> 75 | U13: GPT-4 | X13: 100 | Y13: GPT-4 | AB13: 90 | AC13: LLaMA, BLOOM, BERT | AD13: 80 | AE13: 90 | AF13: =AVERAGE(AD13:AE13) -> 85 | AG13: Claude, GPT-4 | AJ13: 100 | AK13: GPT-4 | AN13: 0 | AO13: NA | AR13: Qwen3-235b-a22b | AS13: =AJ15 -> 98.75 | AT13: =AVERAGE(D13,H13,L13,T13,X13,AB13,AF13,AJ13,AN13) -> 82.666667
A14: Falcon-H1-3B-Instruct | B14: 95 | C14: 100 | D14: =AVERAGE(B14:C14) -> 97.5 | E14: GPT-4 | H14: 100 | I14: GPT-3.5, GPT-4, Gemini | J14: 92 | K14: 95 | L14: =AVERAGE(J14:K14) -> 93.5 | M14: GPT-4 | Q14: GPT-4 | R14: 70 | S14: 80 | T14: =AVERAGE(R14:S14) -> 75 | U14: GPT-4 | X14: 100 | Y14: GPT-4 | AB14: 80 | AC14: LLaMA, BLOOM, BERT | AD14: 75 | AE14: 85 | AF14: =AVERAGE(AD14:AE14) -> 80 | AG14: Claude, GPT-4 | AJ14: 100 | AK14: GPT-4 | AN14: 0 | AO14: NA | AR14: Falcon-H1-3B-Instruct | AS14: =AN15 -> 0 | AT14: =AVERAGE(D14,H14,L14,T14,X14,AB14,AF14,AJ14,AN14) -> 80.666667
A15: Mean | D15: =AVERAGE(D5:D14) -> 96.5 | H15: =AVERAGE(H5:H14) -> 100 | L15: =AVERAGE(L5:L14) -> 92.7 | T15: =AVERAGE(T5:T14) -> 68.5 | X15: =AVERAGE(X5:X14) -> 100 | AB15: =AVERAGE(AB5:AB14) -> 59 | AF15: =AVERAGE(AF5:AF14) -> 79.25 | AJ15: =AVERAGE(AJ5:AJ14) -> 98.75 | AN15: =AVERAGE(AN5:AN14) -> 0
AR25: Model | AS25: Ability to detect
AR26: Falcon-H1-3B-Instruct | AS26: 0
AR27: Llama-4-Scout-nitro | AS27: 59
AR28: Perplexity | AS28: 68.5
AR29: Grok-3 | AS29: 79.25
AR30: Claude Sonnet 4 | AS30: 92.7
AR31: ChatGPT-4o | AS31: 96.5
AR32: Qwen3-235b-a22b | AS32: 98.75
AR33: Gemini 2.5 Pro | AS33: 100
AR34: DeepSeek V3 | AS34: 100
AR35: Mistral Le Chat
AR39: Model | AS39: Ability to be detected
AR40: Perplexity | AS40: 71.944444
AR41: ChatGPT-4o | AS41: 72.5
AR42: Claude Sonnet 4 | AS42: 73.055556
AR43: Grok-3 | AS43: 73.888889
AR44: Gemini 2.5 Pro | AS44: 76.277778
AR45: Mistral Le Chat | AS45: 78.5
AR46: Llama-4-Scout-nitro | AS46: 80.277778
AR47: Falcon-H1-3B-Instruct | AS47: 80.666667
AR48: DeepSeek V3 | AS48: 82.111111
AR49: Qwen3-235b-a22b | AS49: 82.666667

Sheet Task-3 FSM
B2: Detecting Models
B3: ChatGPT-4o | F3: Gemini 2.5 Pro | J3: Claude Sonnet 4 | N3: Mistral Le Chat | R3: Perplexity | V3: DeepSeek V3 | Z3: Llama-4-Scout-nitro | AD3: Grok-3 | AH3: Qwen3-235b-a22b | AL3: Falcon-H1-3B-Instruct
A4: Generating Models | B4: Min Percent | C4: Max Percent | D4: Avg. Percent | E4: Suggested Models | F4: Min Percent | G4: Max Percent | H4: Avg. Percent | I4: Suggested Models | J4: Min Percent | K4: Max Percent | L4: Avg. Percent | M4: Suggested Models | N4: Min Percent | O4: Max Percent | P4: Avg. Percent | Q4: Suggested Models | R4: Min Percent | S4: Max Percent | T4: Avg. Percent | U4: Suggested Models | V4: Min Percent | W4: Max Percent | X4: Avg. Percent | Y4: Suggested Models | Z4: Min Percent | AA4: Max Percent | AB4: Avg. Percent | AC4: Suggested Models | AD4: Min Percent | AE4: Max Percent | AF4: Avg. Percent | AG4: Suggested Models | AH4: Min Percent | AI4: Max Percent | AJ4: Avg. Percent | AK4: Suggested Models | AL4: Min Percent | AM4: Max Percent | AN4: Avg. Percent | AO4: Suggested Models | AR4: Model | AS4: Ability to detect | AT4: Ability to be detected
A5: ChatGPT-4o | B5: 85 | C5: 95 | D5: =AVERAGE(B5:C5) -> 90 | E5: GPT-3.5, GPT-4 | H5: 100 | I5: GPT-4, Gemini, Llama | J5: 85 | K5: 90 | L5: =AVERAGE(J5:K5) -> 87.5 | M5: GPT-3.5, GPT-4 | Q5: Mistral Le Chat | R5: 95 | S5: 100 | T5: =AVERAGE(R5:S5) -> 97.5 | U5: GPT-4, Claude 2/3 | X5: 100 | Y5: GPT-4 | AB5: 80 | AC5: BERT, RoBERTa | AF5: 70 | AG5: Claude | AH5: 95 | AI5: 100 | AJ5: =AVERAGE(AH5:AI5) -> 97.5 | AK5: GPT-3.5, GPT-4 | AN5: 0 | AO5: NA | AR5: ChatGPT-4o | AS5: =D15 -> 91 | AT5: =AVERAGE(D5,H5,L5,T5,X5,AB5,AF5,AJ5,AN5) -> 80.277778
A6: Gemini 2.5 Pro | B6: 90 | C6: 95 | D6: =AVERAGE(B6:C6) -> 92.5 | E6: GPT-3.5, GPT-4 | H6: 100 | I6: GPT-4, Gemini | J6: 15 | K6: 20 | L6: =AVERAGE(J6:K6) -> 17.5 | M6: NA | Q6: Human | R6: 95 | S6: 100 | T6: =AVERAGE(R6:S6) -> 97.5 | U6: GPT-4, Claude | X6: 100 | Y6: GPT-4 | AB6: 90 | AC6: BERT, RoBERTa | AF6: 80 | AG6: Claude, GPT-4 | AH6: 90 | AI6: 95 | AJ6: =AVERAGE(AH6:AI6) -> 92.5 | AK6: GPT-3.5 or GPT-4, Gemini 1.0, 1.5, Llama 3 | AN6: 20 | AO6: GPT-4 | AR6: Gemini 2.5 Pro | AS6: =H15 -> 100 | AT6: =AVERAGE(D6,H6,L6,T6,X6,AB6,AF6,AJ6,AN6) -> 76.666667
A7: Claude Sonnet 4 | B7: 85 | C7: 95 | D7: =AVERAGE(B7:C7) -> 90 | E7: GPT-3.5, GPT-4 | H7: 100 | I7: GPT-4, Gemini | J7: 75 | K7: 80 | L7: =AVERAGE(J7:K7) -> 77.5 | M7: GPT-4, Claude, Gemini | Q7: Mistral Le Chat | R7: 90 | S7: 100 | T7: =AVERAGE(R7:S7) -> 95 | U7: GPT-4, Claude | X7: 100 | Y7: GPT-4 | AB7: 85 | AC7: BERT, RoBERTa | AF7: 75 | AG7: Claude, GPT-4 | AJ7: 100 | AK7: GPT-3.5 or GPT-4, Gemini 1.0, 1.5, Llama 3 | AN7: 100 | AO7: GPT-4 | AR7: Claude Sonnet 4 | AS7: =L15 -> 67 | AT7: =AVERAGE(D7,H7,L7,T7,X7,AB7,AF7,AJ7,AN7) -> 91.388889
A8: Mistral Le Chat | B8: 85 | C8: 95 | D8: =AVERAGE(B8:C8) -> 90 | E8: GPT-3.5, GPT-4 | H8: 100 | I8: GPT-4, Gemini | J8: 90 | K8: 95 | L8: =AVERAGE(J8:K8) -> 92.5 | M8: GPT-3.5, GPT-4 | Q8: Mistral Le Chat | R8: 90 | S8: 100 | T8: =AVERAGE(R8:S8) -> 95 | U8: GPT-4, Claude 3 | X8: 100 | Y8: GPT-4 | AB8: 95 | AC8: BERT, RoBERTa | AF8: 85 | AG8: Claude, GPT-4 | AJ8: 100 | AK8: GPT-3.5 or GPT-4, Gemini 1.0, 1.5, Llama 3 | AN8: 100 | AO8: GPT-4 | AR8: Mistral Le Chat | AT8: =AVERAGE(D8,H8,L8,T8,X8,AB8,AF8,AJ8,AN8) -> 95.277778
A9: Perplexity | B9: 85 | C9: 95 | D9: =AVERAGE(B9:C9) -> 90 | E9: GPT-3.5, GPT-4 | H9: 100 | I9: GPT-4, Gemini | J9: 25 | K9: 30 | L9: =AVERAGE(J9:K9) -> 27.5 | M9: NA | Q9: Mistral Le Chat | T9: 95 | U9: GPT-4, Claude 3 | X9: 100 | Y9: GPT-4 | AB9: 90 | AC9: BERT, RoBERTa | AF9: 80 | AG9: Claude, GPT-4 | AJ9: 100 | AK9: GPT-3.5 or GPT-4, Gemini 1.0, 1.5, Llama 3 | AN9: 100 | AO9: GPT-4 | AR9: Perplexity | AS9: =T15 -> 95.5 | AT9: =AVERAGE(D9,H9,L9,T9,X9,AB9,AF9,AJ9,AN9) -> 86.944444
A10: DeepSeek V3 | B10: 90 | C10: 95 | D10: =AVERAGE(B10:C10) -> 92.5 | E10: GPT-3.5, GPT-4 | H10: 100 | I10: GPT-4, Gemini | J10: 85 | K10: 90 | L10: =AVERAGE(J10:K10) -> 87.5 | M10: GPT-3.5, GPT-4 | Q10: Mistral Le Chat | R10: 90 | S10: 100 | T10: =AVERAGE(R10:S10) -> 95 | U10: GPT-4, Claude 3 | X10: 100 | Y10: GPT-4 | AB10: 92 | AC10: BERT, RoBERTa | AF10: 80 | AG10: Claude, GPT-4 | AJ10: 100 | AK10: GPT-3.5 or GPT-4, Gemini 1.0, 1.5, Llama 3 | AN10: 100 | AO10: GPT-4 | AR10: DeepSeek V3 | AS10: =X15 -> 100 | AT10: =AVERAGE(D10,H10,L10,T10,X10,AB10,AF10,AJ10,AN10) -> 94.111111
A11: Llama-4-Scout-nitro | B11: 90 | C11: 95 | D11: =AVERAGE(B11:C11) -> 92.5 | E11: GPT-3.5, GPT-4 | H11: 100 | I11: GPT-4, Gemini | J11: 90 | K11: 95 | L11: =AVERAGE(J11:K11) -> 92.5 | M11: GPT-4, Claude | Q11: Mistral Le Chat | R11: 90 | S11: 100 | T11: =AVERAGE(R11:S11) -> 95 | U11: GPT-4, Claude | X11: 100 | Y11: GPT-4 | AB11: 95 | AC11: BERT, RoBERTa | AF11: 85 | AG11: Claude, GPT-4 | AJ11: 100 | AK11: GPT-3.5 or GPT-4, Gemini 1.0, 1.5, Llama 3 | AN11: 100 | AO11: GPT-4 | AR11: Llama-4-Scout-nitro | AS11: =AB15 -> 88.2 | AT11: =AVERAGE(D11,H11,L11,T11,X11,AB11,AF11,AJ11,AN11) -> 95.555556
A12: Grok-3 | B12: 85 | C12: 95 | D12: =AVERAGE(B12:C12) -> 90 | E12: GPT-3.5, GPT-4 | H12: 100 | I12: GPT-4, Gemini, Llama 3 | J12: 25 | K12: 30 | L12: =AVERAGE(J12:K12) -> 27.5 | M12: NA | Q12: Mistral Le Chat | R12: 90 | S12: 100 | T12: =AVERAGE(R12:S12) -> 95 | U12: GPT-4, Claude 3 | X12: 100 | Y12: GPT-4 | AB12: 80 | AC12: BERT, RoBERTa | AF12: 75 | AG12: Claude, GPT-4 | AJ12: 100 | AK12: GPT-3.5 or GPT-4, Gemini 1.0, 1.5, Llama 3 | AN12: 100 | AO12: GPT-4 | AR12: Grok-3 | AS12: =AF15 -> 79 | AT12: =AVERAGE(D12,H12,L12,T12,X12,AB12,AF12,AJ12,AN12) -> 85.277778
A13: Qwen3-235b-a22b | B13: 88 | C13: 95 | D13: =AVERAGE(B13:C13) -> 91.5 | E13: GPT-3.5, GPT-4 | H13: 100 | I13: GPT-4, Gemini, Llama 3 | J13: 80 | K13: 85 | L13: =AVERAGE(J13:K13) -> 82.5 | M13: GPT-4, Claude | Q13: Mistral Le Chat | R13: 90 | S13: 100 | T13: =AVERAGE(R13:S13) -> 95 | U13: GPT-4, Claude 3 | X13: 100 | Y13: GPT-4 | AB13: 85 | AC13: BERT, RoBERTa | AF13: 80 | AG13: Claude, GPT-4 | AJ13: 100 | AK13: GPT-3.5 or GPT-4, Gemini 1.0, 1.5, Llama 3 | AN13: 100 | AO13: GPT-4 | AR13: Qwen3-235b-a22b | AS13: =AJ15 -> 99 | AT13: =AVERAGE(D13,H13,L13,T13,X13,AB13,AF13,AJ13,AN13) -> 92.666667
A14: Falcon-H1-3B-Instruct | B14: 88 | C14: 94 | D14: =AVERAGE(B14:C14) -> 91 | E14: GPT-3.5, GPT-4 | H14: 100 | I14: GPT-4, Gemini | J14: 75 | K14: 80 | L14: =AVERAGE(J14:K14) -> 77.5 | M14: GPT-4, Claude | Q14: Mistral Le Chat | R14: 90 | S14: 100 | T14: =AVERAGE(R14:S14) -> 95 | U14: GPT-4, Claude 3 | X14: 100 | Y14: GPT-4 | AB14: 90 | AC14: BERT, RoBERTa | AF14: 80 | AG14: Claude, GPT-4 | AJ14: 100 | AK14: GPT-3.5 or GPT-4, Gemini 1.0, 1.5, Llama 3 | AN14: 70 | AO14: GPT-4 | AR14: Falcon-H1-3B-Instruct | AS14: =AN15 -> 79 | AT14: =AVERAGE(D14,H14,L14,T14,X14,AB14,AF14,AJ14,AN14) -> 89.277778
A15: Mean | D15: =AVERAGE(D5:D14) -> 91 | H15: =AVERAGE(H5:H14) -> 100 | L15: =AVERAGE(L5:L14) -> 67 | T15: =AVERAGE(T5:T14) -> 95.5 | X15: =AVERAGE(X5:X14) -> 100 | AB15: =AVERAGE(AB5:AB14) -> 88.2 | AF15: =AVERAGE(AF5:AF14) -> 79 | AJ15: =AVERAGE(AJ5:AJ14) -> 99 | AN15: =AVERAGE(AN5:AN14) -> 79
AR25: Model | AS25: Ability to detect
AR26: Claude Sonnet 4 | AS26: 67
AR27: Grok-3 | AS27: 79
AR28: Falcon-H1-3B-Instruct | AS28: 79
AR29: Llama-4-Scout-nitro | AS29: 88.2
AR30: ChatGPT-4o | AS30: 91
AR31: Perplexity | AS31: 95.5
AR32: Qwen3-235b-a22b | AS32: 99
AR33: Gemini 2.5 Pro | AS33: 100
AR34: DeepSeek V3 | AS34: 100
AR35: Mistral Le Chat
AR39: Model | AS39: Ability to be detected
AR40: Gemini 2.5 Pro | AS40: 76.666667
AR41: ChatGPT-4o | AS41: 80.277778
AR42: Grok-3 | AS42: 85.277778
AR43: Perplexity | AS43: 86.944444
AR44: Falcon-H1-3B-Instruct | AS44: 89.277778
AR45: Claude Sonnet 4 | AS45: 91.388889
AR46: Qwen3-235b-a22b | AS46: 92.666667
AR47: DeepSeek V3 | AS47: 94.111111
AR48: Mistral Le Chat | AS48: 95.277778
AR49: Llama-4-Scout-nitro | AS49: 95.555556

Sheet Task 4 - I2C
B2: Detecting Models
B3: ChatGPT-4o | F3: Gemini 2.5 Pro | J3: Claude Sonnet 4 | N3: Mistral Le Chat | R3: Perplexity | V3: DeepSeek V3 | Z3: Llama-4-Scout-nitro | AD3: Grok-3 | AH3: Qwen3-235b-a22b | AL3: Falcon-H1-3B-Instruct
A4: Generating Models | B4: Min Percent | C4: Max Percent | D4: Avg. Percent | E4: Suggested Models | F4: Min Percent | G4: Max Percent | H4: Avg. Percent | I4: Suggested Models | J4: Min Percent | K4: Max Percent | L4: Avg. Percent | M4: Suggested Models | N4: Min Percent | O4: Max Percent | P4: Avg. Percent | Q4: Suggested Models | R4: Min Percent | S4: Max Percent | T4: Avg. Percent | U4: Suggested Models | V4: Min Percent | W4: Max Percent | X4: Avg. Percent | Y4: Suggested Models | Z4: Min Percent | AA4: Max Percent | AB4: Avg. Percent | AC4: Suggested Models | AD4: Min Percent | AE4: Max Percent | AF4: Avg. Percent | AG4: Suggested Models | AH4: Min Percent | AI4: Max Percent | AJ4: Avg. Percent | AK4: Suggested Models | AL4: Min Percent | AM4: Max Percent | AN4: Avg. Percent | AO4: Suggested Models | AR4: Model | AS4: Ability to detect | AT4: Ability to be detected
A5: ChatGPT-4o | B5: 90 | C5: 95 | D5: =AVERAGE(B5:C5) -> 92.5 | E5: GPT-4, GPT-4o, Claude 3.5 Sonnet, , Gemini Pro | H5: 100 | I5: GPT-4 | J5: 90 | K5: 95 | L5: =AVERAGE(J5:K5) -> 92.5 | M5: GPT-3.5, GPT-4, Claude, Bard, Gemini | Q5: GPT-4 | R5: 95 | S5: 100 | T5: =AVERAGE(R5:S5) -> 97.5 | U5: GPT-3.5, GPT-4, Claude 3, Gemini | X5: 100 | Y5: GPT-3.5, GPT-4 | AB5: 80 | AC5: LLaMA, BLOOM | AF5: 100 | AG5: GPT-4 | AJ5: 100 | AK5: GPT-4, Gemini, Llama 3 | AN5: 0 | AO5: NA | AR5: ChatGPT-4o | AS5: =D15 -> 89.1 | AT5: =AVERAGE(D5,H5,L5,T5,X5,AB5,AF5,AJ5,AN5) -> 84.722222
A6: Gemini 2.5 Pro | B6: 60 | C6: 70 | D6: =AVERAGE(B6:C6) -> 65 | E6: GPT-4, GPT-4o | H6: 0 | I6: NA | J6: 20 | K6: 30 | L6: =AVERAGE(J6:K6) -> 25 | M6: GPT-4, Claude | Q6: GPT-4 | R6: 95 | S6: 100 | T6: =AVERAGE(R6:S6) -> 97.5 | U6: GPT-3.5, GPT-4, Claude 3, Gemini | X6: 100 | Y6: GPT-3.5, GPT-4 | AB6: 60 | AC6: LLaMA, BLOOM | AF6: 100 | AG6: GPT-4 | AJ6: 100 | AK6: GPT-4, Gemini | AL6: 0 | AM6: 20 | AN6: =AVERAGE(AL6:AM6) -> 10 | AO6: GPT-4 | AR6: Gemini 2.5 Pro | AS6: =H15 -> 90 | AT6: =AVERAGE(D6,H6,L6,T6,X6,AB6,AF6,AJ6,AN6) -> 61.944444
A7: Claude Sonnet 4 | B7: 90 | C7: 95 | D7: =AVERAGE(B7:C7) -> 92.5 | E7: GPT-4, GPT-4o | H7: 100 | I7: GPT-4 | J7: 85 | K7: 90 | L7: =AVERAGE(J7:K7) -> 87.5 | M7: GPT-4, Claude | Q7: GPT-4 | R7: 90 | S7: 100 | T7: =AVERAGE(R7:S7) -> 95 | U7: GPT-3.5, GPT-4, Claude 3 | X7: 95 | Y7: GPT-4 | AB7: 70 | AC7: LLaMA, BLOOM | AF7: 100 | AG7: GPT-4 | AJ7: 100 | AK7: GPT-4, Gemini, Llama 3 | AL7: 0 | AM7: 20 | AN7: =AVERAGE(AL7:AM7) -> 10 | AO7: GPT-4 | AR7: Claude Sonnet 4 | AS7: =L15 -> 76.65 | AT7: =AVERAGE(D7,H7,L7,T7,X7,AB7,AF7,AJ7,AN7) -> 83.333333
A8: Mistral Le Chat | B8: 85 | C8: 90 | D8: =AVERAGE(B8:C8) -> 87.5 | E8: GPT-4, GPT-4o | H8: 100 | I8: GPT-4 | J8: 90 | K8: 95 | L8: =AVERAGE(J8:K8) -> 92.5 | M8: GPT-3.5, GPT-4, Claude, Bard, Gemini | Q8: GPT-4 | R8: 90 | S8: 100 | T8: =AVERAGE(R8:S8) -> 95 | U8: GPT-3.5, GPT-4, Claude 3 | V8: 90 | W8: 95 | X8: =AVERAGE(V8:W8) -> 92.5 | Y8: GPT-4 | AB8: 80 | AC8: LLaMA, BLOOM | AF8: 100 | AG8: GPT-4 | AJ8: 100 | AK8: GPT-4, Gemini, Llama 3 | AL8: 0 | AM8: 20 | AN8: =AVERAGE(AL8:AM8) -> 10 | AO8: GPT-4 | AR8: Mistral Le Chat | AS8: =P15 -> 50 | AT8: =AVERAGE(D8,H8,L8,T8,X8,AB8,AF8,AJ8,AN8) -> 84.166667
A9: Perplexity | B9: 90 | C9: 95 | D9: =AVERAGE(B9:C9) -> 92.5 | E9: GPT-4, GPT-4o | H9: 100 | I9: GPT-4 | J9: 15 | K9: 25 | L9: =AVERAGE(J9:K9) -> 20 | M9: GPT, Claude | Q9: GPT-4 | R9: 90 | S9: 100 | T9: =AVERAGE(R9:S9) -> 95 | U9: GPT-4, Claude 3 | X9: 100 | Y9: GPT-4 | AB9: 75 | AC9: LLaMA, BLOOM | AF9: 100 | AG9: GPT-4 | AJ9: 100 | AK9: GPT-4, Gemini, Llama 3 | AL9: 0 | AM9: 20 | AN9: =AVERAGE(AL9:AM9) -> 10 | AO9: GPT-4 | AR9: Perplexity | AS9: =T15 -> 94 | AT9: =AVERAGE(D9,H9,L9,T9,X9,AB9,AF9,AJ9,AN9) -> 76.944444
A10: DeepSeek V3 | B10: 92 | C10: 96 | D10: =AVERAGE(B10:C10) -> 94 | E10: GPT-4, GPT-4o | H10: 100 | I10: GPT-4 | J10: 95 | K10: 98 | L10: =AVERAGE(J10:K10) -> 96.5 | M10: GPT-3.5, GPT-4, Claude, Bard, Gemini | Q10: GPT-4 | R10: 90 | S10: 100 | T10: =AVERAGE(R10:S10) -> 95 | U10: GPT-3.5, GPT-4, Claude 3 | V10: 85 | W10: 90 | X10: =AVERAGE(V10:W10) -> 87.5 | Y10: GPT-4, Claude 3 | AB10: 90 | AC10: LLaMA, BLOOM | AF10: 100 | AG10: GPT-4 | AJ10: 100 | AK10: GPT-4, Gemini, Llama 3 | AL10: 0 | AM10: 20 | AN10: =AVERAGE(AL10:AM10) -> 10 | AO10: GPT-4 | AR10: DeepSeek V3 | AS10: =X15 -> 96.25 | AT10: =AVERAGE(D10,H10,L10,T10,X10,AB10,AF10,AJ10,AN10) -> 85.888889
A11: Llama-4-Scout-nitro | B11: 80 | C11: 85 | D11: =AVERAGE(B11:C11) -> 82.5 | E11: GPT-4, GPT-4o | H11: 100 | I11: GPT-4 | J11: 90 | K11: 95 | L11: =AVERAGE(J11:K11) -> 92.5 | M11: GPT-3.5, GPT-4, Claude, GitHub, | Q11: GPT-4 | R11: 85 | S11: 95 | T11: =AVERAGE(R11:S11) -> 90 | U11: GPT-4, Claude | W11: 95 | X11: =AVERAGE(V11:W11) -> 95 | Y11: GPT-4, Claude 3 | AB11: 85 | AC11: LLaMA, BLOOM | AF11: 100 | AG11: GPT-4 | AJ11: 85 | AK11: GPT-4, Gemini, Llama 3 | AL11: 0 | AM11: 20 | AN11: =AVERAGE(AL11:AM11) -> 10 | AO11: GPT-4 | AR11: Llama-4-Scout-nitro | AS11: =AB15 -> 79 | AT11: =AVERAGE(D11,H11,L11,T11,X11,AB11,AF11,AJ11,AN11) -> 82.222222
A12: Grok-3 | B12: 90 | C12: 94 | D12: =AVERAGE(B12:C12) -> 92 | E12: GPT-4, GPT-4o | H12: 100 | I12: GPT-4 | J12: 75 | K12: 85 | L12: =AVERAGE(J12:K12) -> 80 | M12: GPT-4, Claude | Q12: GPT-4 | R12: 90 | S12: 100 | T12: =AVERAGE(R12:S12) -> 95 | U12: GPT-3.5, GPT-4, Claude 3 | V12: 90 | W12: 95 | X12: =AVERAGE(V12:W12) -> 92.5 | Y12: GPT-4, Claude 3 | AB12: 80 | AC12: LLaMA, BLOOM | AF12: 100 | AG12: GPT-4 | AJ12: 100 | AK12: GPT-3.5 or GPT-4, Gemini 1.0, 1.5, Llama 3 | AN12: 0 | AO12: NA | AR12: Grok-3 | AS12: =AF15 -> 100 | AT12: =AVERAGE(D12,H12,L12,T12,X12,AB12,AF12,AJ12,AN12) -> 82.166667
A13: Qwen3-235b-a22b | B13: 90 | C13: 100 | D13: =AVERAGE(B13:C13) -> 95 | E13: GPT-4, Claude 3 | G13: Pro | H13: 100 | I13: GPT-4, Gemini | J13: 90 | K13: 95 | L13: =AVERAGE(J13:K13) -> 92.5 | M13: GPT-4, Claude | N13: 40 | O13: 50 | P13: =AVERAGE(N13:O13) -> 45 | Q13: GPT-4 | R13: 90 | S13: 95 | T13: =AVERAGE(R13:S13) -> 92.5 | U13: GPT-4, GPT-4 turbo | X13: 100 | Y13: GPT-4 | AB13: 80 | AC13: BERT, RoBERTa, Longformer | AF13: 100 | AG13: GPT-3.5, GPT-4 | AH13: 60 | AI13: 70 | AJ13: =AVERAGE(AH13:AI13) -> 65 | AK13: GPT-3.5 or GPT-4, Claude 3, Llama | AN13: 0 | AO13: NA | AR13: Qwen3-235b-a22b | AS13: =AJ15 -> 93.25 | AT13: =AVERAGE(D13,H13,L13,T13,X13,AB13,AF13,AJ13,AN13) -> 80.555556
A14: Falcon-H1-3B-Instruct | B14: 95 | C14: 100 | D14: =AVERAGE(B14:C14) -> 97.5 | E14: GPT-4 | G14: Pro | H14: 100 | I14: GPT-3.5 | J14: 85 | K14: 90 | L14: =AVERAGE(J14:K14) -> 87.5 | M14: GPT-3.5, GPT-4 | N14: 50 | O14: 60 | P14: =AVERAGE(N14:O14) -> 55 | Q14: GPT-4 | R14: 85 | S14: 90 | T14: =AVERAGE(R14:S14) -> 87.5 | U14: GPT-4, GPT-4 turbo | X14: 100 | Y14: GPT-4 | AB14: 90 | AC14: BERT, RoBERTa, T5 | AF14: 100 | AG14: GPT-3.5, GPT-4 | AH14: 80 | AI14: 85 | AJ14: =AVERAGE(AH14:AI14) -> 82.5 | AK14: GPT-3.5 or GPT-4, Llama | AN14: 100 | AO14: GPT-4 | AR14: Falcon-H1-3B-Instruct | AS14: =AN15 -> 16 | AT14: =AVERAGE(D14,H14,L14,T14,X14,AB14,AF14,AJ14,AN14) -> 93.888889
A15: Mean | D15: =AVERAGE(D5:D14) -> 89.1 | H15: =AVERAGE(H5:H14) -> 90 | L15: =AVERAGE(L5:L14) -> 76.65 | P15: =AVERAGE(P5:P14) -> 50 | T15: =AVERAGE(T5:T14) -> 94 | X15: =AVERAGE(X5:X14) -> 96.25 | AB15: =AVERAGE(AB5:AB14) -> 79 | AF15: =AVERAGE(AF5:AF14) -> 100 | AJ15: =AVERAGE(AJ5:AJ14) -> 93.25 | AN15: =AVERAGE(AN5:AN14) -> 16
AR25: Model | AS25: Ability to detect
AR26: Falcon-H1-3B-Instruct | AS26: 16
AR27: Mistral Le Chat | AS27: 50
AR28: Claude Sonnet 4 | AS28: 76.65
AR29: Llama-4-Scout-nitro | AS29: 79
AR30: ChatGPT-4o | AS30: 89.1
AR31: Gemini 2.5 Pro | AS31: 90
AR32: Qwen3-235b-a22b | AS32: 93.25
AR33: Perplexity | AS33: 94
AR34: DeepSeek V3 | AS34: 96.25
AR35: Grok-3 | AS35: 100
AR39: Model | AS39: Ability to be detected
AR40: Gemini 2.5 Pro | AS40: 61.944444
AR41: Perplexity | AS41: 76.944444
AR42: Qwen3-235b-a22b | AS42: 80.555556
AR43: Grok-3 | AS43: 82.166667
AR44: Llama-4-Scout-nitro | AS44: 82.222222
AR45: Claude Sonnet 4 | AS45: 83.333333
AR46: Mistral Le Chat | AS46: 84.166667
AR47: ChatGPT-4o | AS47: 84.722222
AR48: DeepSeek V3 | AS48: 85.888889
AR49: Falcon-H1-3B-Instruct | AS49: 93.888889

Sheet Task 5 -MPI
B2: Detecting Models
B3: ChatGPT-4o | F3: Gemini 2.5 Pro | J3: Claude Sonnet 4 | N3: Mistral Le Chat | R3: Perplexity | V3: DeepSeek V3 | Z3: Llama-4-Scout-nitro | AD3: Grok-3 | AH3: Qwen3-235b-a22b | AL3: Falcon-H1-3B-Instruct
A4: Generating Models | B4: Min Percent | C4: Max Percent | D4: Avg. Percent | E4: Suggested Models | F4: Min Percent | G4: Max Percent | H4: Avg. Percent | I4: Suggested Models | J4: Min Percent | K4: Max Percent | L4: Avg. Percent | M4: Suggested Models | N4: Min Percent | O4: Max Percent | P4: Avg. Percent | Q4: Suggested Models | R4: Min Percent | S4: Max Percent | T4: Avg. Percent | U4: Suggested Models | V4: Min Percent | W4: Max Percent | X4: Avg. Percent | Y4: Suggested Models | Z4: Min Percent | AA4: Max Percent | AB4: Avg. Percent | AC4: Suggested Models | AD4: Min Percent | AE4: Max Percent | AF4: Avg. Percent | AG4: Suggested Models | AH4: Min Percent | AI4: Max Percent | AJ4: Avg. Percent | AK4: Suggested Models | AL4: Min Percent | AM4: Max Percent | AN4: Avg. Percent | AO4: Suggested Models | AR4: Model | AS4: Ability to detect | AT4: Ability to be detected
A5: ChatGPT-4o | B5: 95 | C5: 100 | D5: =AVERAGE(B5:C5) -> 97.5 | E5: GPT-4 | H5: 100 | I5: GPT-4, Gemini | J5: 85 | K5: 90 | L5: =AVERAGE(J5:K5) -> 87.5 | M5: GPT-3.5, GPT-4 | Q5: GPT-4, BARD, Claude | T5: 85 | U5: GPT-4, Claude 3 | X5: 100 | Y5: GPT-3, GPT-4 | AB5: 80 | AC5: LLaMA, BART, RoBERTa | AF5: 100 | AG5: GPT-4, GPT-4o | AJ5: 100 | AK5: GPT-3.5 or GPT-4 | AN5: 0 | AO5: NA | AR5: ChatGPT-4o | AS5: =D15 -> 93 | AT5: =AVERAGE(D5,H5,L5,T5,X5,AB5,AF5,AJ5,AN5) -> 83.333333
A6: Gemini 2.5 Pro | B6: 80 | C6: 90 | D6: =AVERAGE(B6:C6) -> 85 | E6: GPT-4, Claude 3 | H6: 100 | I6: Copilot, Gemini | J6: 20 | K6: 30 | L6: =AVERAGE(J6:K6) -> 25 | M6: Grammerly, GPT | Q6: GPT-4, Claude, Gemini | R6: 90 | S6: 95 | T6: =AVERAGE(R6:S6) -> 92.5 | U6: GPT-4, Claude 3, Gemini Advanced | X6: 100 | Y6: GPT-4 | AB6: 90 | AC6: LLaMA, BART, RoBERTa | AF6: 70 | AG6: GPT-4 | AJ6: 100 | AK6: GPT-3.5 or GPT-4 | AN6: 100 | AO6: GPT-4 | AR6: Gemini 2.5 Pro | AS6: =H15 -> 98.25 | AT6: =AVERAGE(D6,H6,L6,T6,X6,AB6,AF6,AJ6,AN6) -> 84.722222
A7: Claude Sonnet 4 | B7: 90 | C7: 100 | D7: =AVERAGE(B7:C7) -> 95 | E7: GPT-4, Claude 3 | H7: 100 | I7: GPT-4, Gemini | J7: 90 | K7: 95 | L7: =AVERAGE(J7:K7) -> 92.5 | M7: GPT-4 | N7: 90 | O7: 95 | P7: =AVERAGE(N7:O7) -> 92.5 | Q7: GPT-4, Claude 3, Gemini 1.5 | R7: 85 | S7: 90 | T7: =AVERAGE(R7:S7) -> 87.5 | U7: GPT-4, GPT-4o, Claude 3, Gemini Advanced | X7: 95 | Y7: GPT-4, Claude 3 | AB7: 85 | AC7: LLaMA, BART, RoBERTa | AF7: 90 | AG7: GPT-4 | AJ7: 100 | AK7: GPT-3.5 or GPT-4 | AN7: 100 | AO7: GPT-4 | AR7: Claude Sonnet 4 | AS7: =L15 -> 78.65 | AT7: =AVERAGE(D7,H7,L7,T7,X7,AB7,AF7,AJ7,AN7) -> 93.888889
A8: Mistral Le Chat | B8: 90 | C8: 95 | D8: =AVERAGE(B8:C8) -> 92.5 | E8: GPT-4, Claude 3 | H8: 100 | I8: GPT-4, Gemini | J8: 95 | K8: 98 | L8: =AVERAGE(J8:K8) -> 96.5 | M8: GPT-3.5, GPT-4 | N8: 95 | O8: 100 | P8: =AVERAGE(N8:O8) -> 97.5 | Q8: GPT-4, Claude 3, Gemini 1.5 | R8: 85 | S8: 90 | T8: =AVERAGE(R8:S8) -> 87.5 | U8: GPT-4, GPT-4o, Claude 3, Gemini Advanced | V8: 95 | W8: 100 | X8: =AVERAGE(V8:W8) -> 97.5 | Y8: GPT-4, Claude 3 | AB8: 80 | AC8: BART, RoBERTa | AF8: 80 | AG8: GPT-4, GPT-4o | AH8: 90 | AI8: 95 | AJ8: =AVERAGE(AH8:AI8) -> 92.5 | AK8: GPT-3.5 or GPT-4 | AN8: 100 | AO8: GPT-4 | AR8: Mistral Le Chat | AS8: =P15 -> 94.875 | AT8: =AVERAGE(D8,H8,L8,T8,X8,AB8,AF8,AJ8,AN8) -> 91.833333
A9: Perplexity | B9: 90 | C9: 95 | D9: =AVERAGE(B9:C9) -> 92.5 | E9: GPT-4 | H9: 100 | I9: GPT-4, Gemini | J9: 85 | K9: 90 | L9: =AVERAGE(J9:K9) -> 87.5 | M9: GPT-4 | N9: 95 | O9: 100 | P9: =AVERAGE(N9:O9) -> 97.5 | Q9: GPT-4, Claude 3, Gemini 1.5 | R9: 85 | S9: 90 | T9: =AVERAGE(R9:S9) -> 87.5 | U9: GPT-4, GPT-4o, Claude 3, Gemini Advanced | V9: 85 | W9: 95 | X9: =AVERAGE(V9:W9) -> 90 | Y9: GPT-4, Claude 3 | AB9: 90 | AC9: LLaMA, RoBERTa | AF9: 85 | AG9: GPT-4 | AH9: 95 | AI9: 100 | AJ9: =AVERAGE(AH9:AI9) -> 97.5 | AK9: GPT-4 | AN9: 100 | AO9: GPT-4 | AR9: Perplexity | AS9: =T15 -> 87.75 | AT9: =AVERAGE(D9,H9,L9,T9,X9,AB9,AF9,AJ9,AN9) -> 92.222222
A10: DeepSeek V3 | B10: 95 | C10: 100 | D10: =AVERAGE(B10:C10) -> 97.5 | E10: GPT-4, Claude 3 | F10: 95 | G10: 100 | H10: =AVERAGE(F10:G10) -> 97.5 | I10: GPT-4, Gemini | J10: 95 | K10: 98 | L10: =AVERAGE(J10:K10) -> 96.5 | M10: GPT-3.5, GPT-4 | N10: 95 | O10: 100 | P10: =AVERAGE(N10:O10) -> 97.5 | Q10: GPT-4, Claude 3, Gemini 1.5 | R10: 85 | S10: 90 | T10: =AVERAGE(R10:S10) -> 87.5 | U10: GPT-4, GPT-4o, Claude 3, Gemini Advanced | V10: 90 | W10: 95 | X10: =AVERAGE(V10:W10) -> 92.5 | Y10: GPT-4, Claude 3 | AB10: 95 | AC10: LLaMA, RoBERTa | AF10: 90 | AG10: GPT-4 | AH10: 95 | AI10: 100 | AJ10: =AVERAGE(AH10:AI10) -> 97.5 | AK10: GPT-4 | AN10: 100 | AO10: GPT-4 | AR10: DeepSeek V3 | AS10: =X15 -> 96.7 | AT10: =AVERAGE(D10,H10,L10,T10,X10,AB10,AF10,AJ10,AN10) -> 94.888889
A11: Llama-4-Scout-nitro | B11: 90 | C11: 95 | D11: =AVERAGE(B11:C11) -> 92.5 | E11: GPT-4, Claude 3 | F11: 95 | G11: 100 | H11: =AVERAGE(F11:G11) -> 97.5 | I11: GPT-4, Gemini | J11: 92 | K11: 95 | L11: =AVERAGE(J11:K11) -> 93.5 | M11: GPT-3.5, GPT-4 | N11: 95 | O11: 100 | P11: =AVERAGE(N11:O11) -> 97.5 | Q11: GPT-4, Claude 3, Gemini 1.5 | R11: 85 | S11: 90 | T11: =AVERAGE(R11:S11) -> 87.5 | U11: GPT-4, GPT-4o, Claude 3, Gemini Advanced | V11: 97 | W11: 100 | X11: =AVERAGE(V11:W11) -> 98.5 | Y11: GPT-4 | AB11: 92 | AC11: LLaMA, RoBERTa | AF11: 95 | AG11: GPT-4 | AH11: 90 | AI11: 95 | AJ11: =AVERAGE(AH11:AI11) -> 92.5 | AK11: GPT-3.5 or GPT-4 | AN11: 100 | AO11: GPT-4 | AR11: Llama-4-Scout-nitro | AS11: =AB15 -> 88.2 | AT11: =AVERAGE(D11,H11,L11,T11,X11,AB11,AF11,AJ11,AN11) -> 94.333333
A12: Grok-3 | B12: 85 | C12: 90 | D12: =AVERAGE(B12:C12) -> 87.5 | E12: GPT-4, Claude 3 | F12: 90 | G12: 95 | H12: =AVERAGE(F12:G12) -> 92.5 | I12: GPT-4, Gemini | J12: 88 | K12: 92 | L12: =AVERAGE(J12:K12) -> 90 | M12: GPT-4 | N12: 90 | O12: 95 | P12: =AVERAGE(N12:O12) -> 92.5 | Q12: GPT-4, Claude 3, Gemini 1.5 | R12: 85 | S12: 90 | T12: =AVERAGE(R12:S12) -> 87.5 | U12: GPT-4, GPT-4o, Claude 3, Gemini Advanced | V12: 95 | W12: 99 | X12: =AVERAGE(V12:W12) -> 97 | Y12: GPT-4, Claude 3 | AB12: 95 | AC12: LLaMA | AF12: 90 | AG12: GPT-4 | AH12: 60 | AI12: 70 | AJ12: =AVERAGE(AH12:AI12) -> 65 | AK12: GPT-4 | AN12: 100 | AO12: GPT-4 | AR12: Grok-3 | AS12: =AF15 -> 86.5 | AT12: =AVERAGE(D12,H12,L12,T12,X12,AB12,AF12,AJ12,AN12) -> 89.388889
A13: Qwen3-235b-a22b | B13: 95 | C13: 100 | D13: =AVERAGE(B13:C13) -> 97.5 | E13: GPT-4, Claude 3 | F13: 95 | G13: 100 | H13: =AVERAGE(F13:G13) -> 97.5 | I13: GPT-4, Gemini | J13: 20 | K13: 25 | L13: =AVERAGE(J13:K13) -> 22.5 | M13: NA | N13: 85 | O13: 95 | P13: =AVERAGE(N13:O13) -> 90 | Q13: GPT-4, Claude 3, Gemini 1.5 | R13: 85 | S13: 90 | T13: =AVERAGE(R13:S13) -> 87.5 | U13: GPT-4, GPT-4o, Claude 3, Gemini Advanced | V13: 98 | W13: 100 | X13: =AVERAGE(V13:W13) -> 99 | Y13: GPT-4 | AB13: 90 | AC13: LLaMA, RoBERTa | AF13: 80 | AG13: GPT-4 | AH13: 95 | AI13: 100 | AJ13: =AVERAGE(AH13:AI13) -> 97.5 | AK13: GPT-4 | AN13: 100 | AO13: GPT-4 | AR13: Qwen3-235b-a22b | AS13: =AJ15 -> 93.5 | AT13: =AVERAGE(D13,H13,L13,T13,X13,AB13,AF13,AJ13,AN13) -> 85.722222
A14: Falcon-H1-3B-Instruct | B14: 90 | C14: 95 | D14: =AVERAGE(B14:C14) -> 92.5 | E14: GPT-4, Claude 3 | F14: 95 | G14: 100 | H14: =AVERAGE(F14:G14) -> 97.5 | I14: GPT-4, Gemini | J14: 93 | K14: 97 | L14: =AVERAGE(J14:K14) -> 95 | M14: GPT-3.5, GPT-4 | N14: 90 | O14: 98 | P14: =AVERAGE(N14:O14) -> 94 | Q14: GPT-4, Claude 3, Gemini 1.5 | R14: 85 | S14: 90 | T14: =AVERAGE(R14:S14) -> 87.5 | U14: GPT-4, GPT-4o, Claude 3, Gemini Advanced | V14: 95 | W14: 100 | X14: =AVERAGE(V14:W14) -> 97.5 | Y14: GPT-4 | AB14: 85 | AC14: BART, RoBERTa | AF14: 85 | AG14: GPT-4 | AH14: 90 | AI14: 95 | AJ14: =AVERAGE(AH14:AI14) -> 92.5 | AK14: GPT-3.5 or GPT-4 | AN14: 100 | AO14: GPT-4 | AR14: Falcon-H1-3B-Instruct | AS14: =AN15 -> 90 | AT14: =AVERAGE(D14,H14,L14,T14,X14,AB14,AF14,AJ14,AN14) -> 92.5
A15: Mean | D15: =AVERAGE(D5:D14) -> 93 | H15: =AVERAGE(H5:H14) -> 98.25 | L15: =AVERAGE(L5:L14) -> 78.65 | P15: =AVERAGE(P7:P14) -> 94.875 | T15: =AVERAGE(T5:T14) -> 87.75 | X15: =AVERAGE(X5:X14) -> 96.7 | AB15: =AVERAGE(AB5:AB14) -> 88.2 | AF15: =AVERAGE(AF5:AF14) -> 86.5 | AJ15: =AVERAGE(AJ5:AJ14) -> 93.5 | AN15: =AVERAGE(AN5:AN14) -> 90
AR25: Model | AS25: Ability to detect
AR26: Claude Sonnet 4 | AS26: 78.65
AR27: Grok-3 | AS27: 86.5
AR28: Perplexity | AS28: 87.75
AR29: Llama-4-Scout-nitro | AS29: 88.2
AR30: Falcon-H1-3B-Instruct | AS30: 90
AR31: ChatGPT-4o | AS31: 93
AR32: Qwen3-235b-a22b | AS32: 93.5
AR33: Mistral Le Chat | AS33: 94.875
AR34: DeepSeek V3 | AS34: 96.7
AR35: Gemini 2.5 Pro | AS35: 98.25
AR39: Model | AS39: Ability to be detected
AR40: ChatGPT-4o | AS40: 83.333333
AR41: Gemini 2.5 Pro | AS41: 84.722222
AR42: Qwen3-235b-a22b | AS42: 85.722222
AR43: Grok-3 | AS43: 89.388889
AR44: Mistral Le Chat | AS44: 91.833333
AR45: Perplexity | AS45: 92.222222
AR46: Falcon-H1-3B-Instruct | AS46: 92.5
AR47: Claude Sonnet 4 | AS47: 93.888889
AR48: Llama-4-Scout-nitro | AS48: 94.333333
AR49: DeepSeek V3 | AS49: 94.888889

Sheet Task 6-MR
B2: Detecting Models
B3: ChatGPT-4o | F3: Gemini 2.5 Pro | J3: Claude Sonnet 4 | N3: Mistral Le Chat | R3: Perplexity | V3: DeepSeek V3 | Z3: Llama-4-Scout-nitro | AD3: Grok-3 | AH3: Qwen3-235b-a22b | AL3: Falcon-H1-3B-Instruct
A4: Generating Models | B4: Min Percent | C4: Max Percent | D4: Avg. Percent | E4: Suggested Models | F4: Min Percent | G4: Max Percent | H4: Avg. Percent | I4: Suggested Models | J4: Min Percent | K4: Max Percent | L4: Avg. Percent | M4: Suggested Models | N4: Min Percent | O4: Max Percent | P4: Avg. Percent | Q4: Suggested Models | R4: Min Percent | S4: Max Percent | T4: Avg. Percent | U4: Suggested Models | V4: Min Percent | W4: Max Percent | X4: Avg. Percent | Y4: Suggested Models | Z4: Min Percent | AA4: Max Percent | AB4: Avg. Percent | AC4: Suggested Models | AD4: Min Percent | AE4: Max Percent | AF4: Avg. Percent | AG4: Suggested Models | AH4: Min Percent | AI4: Max Percent | AJ4: Avg. Percent | AK4: Suggested Models | AL4: Min Percent | AM4: Max Percent | AN4: Avg. Percent | AO4: Suggested Models | AR4: Model | AS4: Ability to detect | AT4: Ability to be detected
A5: ChatGPT-4o | B5: 95 | C5: 100 | D5: =AVERAGE(B5:C5) -> 97.5 | E5: GPT-4, Claude 3 | H5: 100 | I5: GPT-3.5, GPT-4, Gemini | J5: 85 | K5: 90 | L5: =AVERAGE(J5:K5) -> 87.5 | M5: GPT-3.5, GPT-4 | N5: 90 | O5: 100 | P5: =AVERAGE(N5:O5) -> 95 | Q5: GPT 3.5, GPT-4, Gemini, Mistral AI | R5: 85 | S5: 90 | T5: =AVERAGE(R5:S5) -> 87.5 | U5: GPT-3.5, GPT-4 | X5: 100 | Y5: GPT-4 | Z5: 70 | AA5: 80 | AB5: =AVERAGE(Z5:AA5) -> 75 | AC5: LLaMA, BERT | AF5: 100 | AG5: GPT-4 | AH5: 95 | AI5: 100 | AJ5: =AVERAGE(AH5:AI5) -> 97.5 | AK5: GPT-3.5 or GPT-4 | AN5: 0 | AO5: NA | AR5: ChatGPT-4o | AS5: =D15 -> 95.75 | AT5: =AVERAGE(D5,H5,L5,T5,X5,AB5,AF5,AJ5,AN5) -> 82.777778
A6: Gemini 2.5 Pro | B6: 90 | C6: 95 | D6: =AVERAGE(B6:C6) -> 92.5 | E6: GPT-4 | H6: 100 | I6: Perplexity AI | L6: 100 | M6: Perplexity AI | N6: 80 | O6: 90 | P6: =AVERAGE(N6:O6) -> 85 | Q6: GPT-4, Gemini, Mistral AI | R6: 90 | S6: 95 | T6: =AVERAGE(R6:S6) -> 92.5 | U6: GPT-3.5, GPT-4 | V6: 80 | W6: 90 | X6: =AVERAGE(V6:W6) -> 85 | Y6: GPT-4 | Z6: 80 | AA6: 90 | AB6: =AVERAGE(Z6:AA6) -> 85 | AC6: LLaMA, T5 | AF6: 70 | AG6: GPT-4, Claude | AH6: 85 | AI6: 90 | AJ6: =AVERAGE(AH6:AI6) -> 87.5 | AK6: GPT-3.5 or GPT-4 | AL6: 90 | AM6: 100 | AN6: =AVERAGE(AL6:AM6) -> 95 | AO6: GPT-4 | AR6: Gemini 2.5 Pro | AS6: =H15 -> 97.4 | AT6: =AVERAGE(D6,H6,L6,T6,X6,AB6,AF6,AJ6,AN6) -> 89.722222
A7: Claude Sonnet 4 | B7: 95 | C7: 100 | D7: =AVERAGE(B7:C7) -> 97.5 | E7: GPT-4 | H7: 100 | I7: GPT-4, Gemini | J7: 20 | K7: 25 | L7: =AVERAGE(J7:K7) -> 22.5 | M7: GPT-4, Claude | N7: 95 | O7: 100 | P7: =AVERAGE(N7:O7) -> 97.5 | Q7: GPT-4, Gemini, Mistral AI | R7: 85 | S7: 90 | T7: =AVERAGE(R7:S7) -> 87.5 | U7: GPT-3.5, GPT-4 | X7: 100 | Y7: GPT-4 | Z7: 90 | AA7: 95 | AB7: =AVERAGE(Z7:AA7) -> 92.5 | AC7: LLaMA, T5 | AF7: 90 | AG7: GPT-4, Claude | AH7: 90 | AI7: 95 | AJ7: =AVERAGE(AH7:AI7) -> 92.5 | AK7: GPT-4 | AL7: 90 | AM7: 100 | AN7: =AVERAGE(AL7:AM7) -> 95 | AO7: GPT-4 | AR7: Claude Sonnet 4 | AS7: =L15 -> 78.65 | AT7: =AVERAGE(D7,H7,L7,T7,X7,AB7,AF7,AJ7,AN7) -> 86.388889
A8: Mistral Le Chat | B8: 90 | C8: 95 | D8: =AVERAGE(B8:C8) -> 92.5 | E8: GPT-4 | H8: 100 | I8: GPT-3.5 | J8: 95 | K8: 98 | L8: =AVERAGE(J8:K8) -> 96.5 | M8: GPT-3.5, GPT-4 | N8: 98 | O8: 100 | P8: =AVERAGE(N8:O8) -> 99 | Q8: GPT-4, Gemini, Mistral AI | R8: 90 | S8: 95 | T8: =AVERAGE(R8:S8) -> 92.5 | U8: GPT-4 | X8: 100 | Y8: GPT-4 | Z8: 85 | AA8: 90 | AB8: =AVERAGE(Z8:AA8) -> 87.5 | AC8: LLaMA, BERT | AF8: 95 | AG8: GPT-4, Claude 3 | AH8: 85 | AI8: 90 | AJ8: =AVERAGE(AH8:AI8) -> 87.5 | AK8: GPT-3.5 | AL8: 90 | AM8: 100 | AN8: =AVERAGE(AL8:AM8) -> 95 | AO8: GPT-4 | AR8: Mistral Le Chat | AS8: =P15 -> 97.35 | AT8: =AVERAGE(D8,H8,L8,T8,X8,AB8,AF8,AJ8,AN8) -> 94.055556
A9: Perplexity | B9: 95 | C9: 100 | D9: =AVERAGE(B9:C9) -> 97.5 | E9: GPT-4, Claude 3 | H9: 95 | I9: GPT-4, Gemini | J9: 75 | K9: 80 | L9: =AVERAGE(J9:K9) -> 77.5 | M9: GPT-4, Claude | N9: 99 | O9: 100 | P9: =AVERAGE(N9:O9) -> 99.5 | Q9: GPT-4, Gemini, Mistral AI | R9: 90 | S9: 93 | T9: =AVERAGE(R9:S9) -> 91.5 | U9: GPT-4 | X9: 100 | Y9: GPT-4 | Z9: 95 | AA9: 100 | AB9: =AVERAGE(Z9:AA9) -> 97.5 | AC9: LLaMA, T5 | AF9: 90 | AG9: GPT-4, Claude 3 | AH9: 95 | AI9: 100 | AJ9: =AVERAGE(AH9:AI9) -> 97.5 | AK9: GPT-4 | AL9: 90 | AM9: 100 | AN9: =AVERAGE(AL9:AM9) -> 95 | AO9: GPT-4 | AR9: Perplexity | AS9: =T15 -> 91.05 | AT9: =AVERAGE(D9,H9,L9,T9,X9,AB9,AF9,AJ9,AN9) -> 93.5
A10: DeepSeek V3 | B10: 95 | C10: 100 | D10: =AVERAGE(B10:C10) -> 97.5 | E10: GPT-4 | H10: 95 | I10: GPT-4, Gemini | J10: 90 | K10: 95 | L10: =AVERAGE(J10:K10) -> 92.5 | M10: GPT-3.5, GPT-4 | N10: 99 | O10: 100 | P10: =AVERAGE(N10:O10) -> 99.5 | Q10: GPT-4, Gemini, Mistral AI | R10: 90 | S10: 95 | T10: =AVERAGE(R10:S10) -> 92.5 | U10: GPT-3.5, GPT-4 | X10: 100 | Y10: GPT-4 | Z10: 90 | AA10: 95 | AB10: =AVERAGE(Z10:AA10) -> 92.5 | AC10: LLaMA, T5 | AF10: 95 | AG10: GPT-4, Claude 3 | AH10: 90 | AI10: 95 | AJ10: =AVERAGE(AH10:AI10) -> 92.5 | AK10: GPT-3.5 or GPT-4 | AL10: 90 | AM10: 100 | AN10: =AVERAGE(AL10:AM10) -> 95 | AO10: GPT-4 | AR10: DeepSeek V3 | AS10: =X15 -> 98.5 | AT10: =AVERAGE(D10,H10,L10,T10,X10,AB10,AF10,AJ10,AN10) -> 94.722222
A11: Llama-4-Scout-nitro | B11: 95 | C11: 100 | D11: =AVERAGE(B11:C11) -> 97.5 | E11: GPT-4, Claude 3 | H11: 95 | I11: GPT-3.5, GPT-4, Gemini | J11: 95 | K11: 98 | L11: =AVERAGE(J11:K11) -> 96.5 | M11: GPT-3.5 | N11: 99 | O11: 100 | P11: =AVERAGE(N11:O11) -> 99.5 | Q11: GPT-4, Gemini, Mistral AI | R11: 90 | S11: 93 | T11: =AVERAGE(R11:S11) -> 91.5 | U11: GPT-4 | X11: 100 | Y11: GPT-4 | AB11: 80 | AC11: LLaMA, BART | AF11: 95 | AG11: GPT-4, Claude 3 | AH11: 85 | AI11: 90 | AJ11: =AVERAGE(AH11:AI11) -> 87.5 | AK11: GPT-3.5 | AL11: 90 | AM11: 100 | AN11: =AVERAGE(AL11:AM11) -> 95 | AO11: GPT-4 | AR11: Llama-4-Scout-nitro | AS11: =AB15 -> 88 | AT11: =AVERAGE(D11,H11,L11,T11,X11,AB11,AF11,AJ11,AN11) -> 93.111111
A12: Grok-3 | B12: 95 | C12: 100 | D12: =AVERAGE(B12:C12) -> 97.5 | E12: GPT-4 | H12: 95 | I12: GPT-4, Gemini | J12: 85 | K12: 90 | L12: =AVERAGE(J12:K12) -> 87.5 | M12: GPT-4, Claude | N12: 99 | O12: 100 | P12: =AVERAGE(N12:O12) -> 99.5 | Q12: GPT-4, Gemini, Mistral AI | R12: 90 | S12: 93 | T12: =AVERAGE(R12:S12) -> 91.5 | U12: GPT-4 | X12: 100 | Y12: GPT-4 | AB12: 90 | AC12: LLaMA, T5 | AF12: 90 | AG12: GPT-4, Claude 3 | AH12: 95 | AI12: 100 | AJ12: =AVERAGE(AH12:AI12) -> 97.5 | AK12: GPT-4 | AL12: 90 | AM12: 100 | AN12: =AVERAGE(AL12:AM12) -> 95 | AO12: GPT-4 | AR12: Grok-3 | AS12: =AF15 -> 91 | AT12: =AVERAGE(D12,H12,L12,T12,X12,AB12,AF12,AJ12,AN12) -> 93.777778
A13: Qwen3-235b-a22b | B13: 95 | C13: 95 | D13: =AVERAGE(B13:C13) -> 95 | E13: GPT-4 | H13: 99 | I13: GPT-4, Gemini | J13: 30 | K13: 35 | L13: =AVERAGE(J13:K13) -> 32.5 | M13: GPT-4, Claude | N13: 99 | O13: 100 | P13: =AVERAGE(N13:O13) -> 99.5 | Q13: GPT-4, Gemini, Mistral AI | R13: 90 | S13: 95 | T13: =AVERAGE(R13:S13) -> 92.5 | U13: GPT-4 | X13: 100 | Y13: GPT-4 | AB13: 95 | AC13: LLaMA, T5 | AF13: 90 | AG13: GPT-4, Claude 3 | AH13: 95 | AI13: 100 | AJ13: =AVERAGE(AH13:AI13) -> 97.5 | AK13: GPT-4 | AL13: 90 | AM13: 100 | AN13: =AVERAGE(AL13:AM13) -> 95 | AO13: GPT-4 | AR13: Qwen3-235b-a22b | AS13: =AJ15 -> 93 | AT13: =AVERAGE(D13,H13,L13,T13,X13,AB13,AF13,AJ13,AN13) -> 88.5
A14: Falcon-H1-3B-Instruct | B14: 90 | C14: 95 | D14: =AVERAGE(B14:C14) -> 92.5 | E14: GPT-4 | H14: 95 | I14: GPT-3.5, GPT-4, Gemini | J14: 92 | K14: 95 | L14: =AVERAGE(J14:K14) -> 93.5 | M14: GPT-3.5, GPT-4 | N14: 99 | O14: 100 | P14: =AVERAGE(N14:O14) -> 99.5 | Q14: GPT-4, Gemini, Mistral AI | R14: 90 | S14: 92 | T14: =AVERAGE(R14:S14) -> 91 | U14: GPT-4 | X14: 100 | Y14: GPT-4 | AB14: 85 | AC14: LLaMA, BART | AF14: 95 | AG14: GPT-4, Claude 3 | AH14: 90 | AI14: 95 | AJ14: =AVERAGE(AH14:AI14) -> 92.5 | AK14: GPT-3.5 or GPT-4 | AL14: 90 | AM14: 100 | AN14: =AVERAGE(AL14:AM14) -> 95 | AO14: GPT-4 | AR14: Falcon-H1-3B-Instruct | AS14: =AN15 -> 85.5 | AT14: =AVERAGE(D14,H14,L14,T14,X14,AB14,AF14,AJ14,AN14) -> 93.277778
A15: Mean | D15: =AVERAGE(D5:D14) -> 95.75 | H15: =AVERAGE(H5:H14) -> 97.4 | L15: =AVERAGE(L5:L14) -> 78.65 | P15: =AVERAGE(P5:P14) -> 97.35 | T15: =AVERAGE(T5:T14) -> 91.05 | X15: =AVERAGE(X5:X14) -> 98.5 | AB15: =AVERAGE(AB5:AB14) -> 88 | AF15: =AVERAGE(AF5:AF14) -> 91 | AJ15: =AVERAGE(AJ5:AJ14) -> 93 | AN15: =AVERAGE(AN5:AN14) -> 85.5
A22: GPT 5 all
AR25: Model | AS25: Ability to detect
AR26: Claude Sonnet 4 | AS26: 78.65
AR27: Falcon-H1-3B-Instruct | AS27: 85.5
AR28: Llama-4-Scout-nitro | AS28: 88
AR29: Grok-3 | AS29: 91
AR30: Perplexity | AS30: 91.05
AR31: Qwen3-235b-a22b | AS31: 93
AR32: ChatGPT-4o | AS32: 95.75
AR33: Mistral Le Chat | AS33: 97.35
AR34: Gemini 2.5 Pro | AS34: 97.4
AR35: DeepSeek V3 | AS35: 98.5
AR39: Model | AS39: Ability to be detected
AR40: ChatGPT-4o | AS40: 82.777778
AR41: Claude Sonnet 4 | AS41: 86.388889
AR42: Qwen3-235b-a22b | AS42: 88.5
AR43: Gemini 2.5 Pro | AS43: 89.722222
AR44: Llama-4-Scout-nitro | AS44: 93.111111
AR45: Falcon-H1-3B-Instruct | AS45: 93.277778
AR46: Perplexity | AS46: 93.5
AR47: Grok-3 | AS47: 93.777778
AR48: Mistral Le Chat | AS48: 94.055556
AR49: DeepSeek V3 | AS49: 94.722222

Sheet Task 7-OOP
B2: Detecting Models
B3: ChatGPT-4o | F3: Gemini 2.5 Pro | J3: Claude Sonnet 4 | N3: Mistral Le Chat | R3: Perplexity | V3: DeepSeek V3 | Z3: Llama-4-Scout-nitro | AD3: Grok-3 | AH3: Qwen3-235b-a22b | AL3: Falcon-H1-3B-Instruct
A4: Generating Models | B4: Min Percent | C4: Max Percent | D4: Avg. Percent | E4: Suggested Models | F4: Min Percent | G4: Max Percent | H4: Avg. Percent | I4: Suggested Models | J4: Min Percent | K4: Max Percent | L4: Avg. Percent | M4: Suggested Models | N4: Min Percent | O4: Max Percent | P4: Avg. Percent | Q4: Suggested Models | R4: Min Percent | S4: Max Percent | T4: Avg. Percent | U4: Suggested Models | V4: Min Percent | W4: Max Percent | X4: Avg. Percent | Y4: Suggested Models | Z4: Min Percent | AA4: Max Percent | AB4: Avg. Percent | AC4: Suggested Models | AD4: Min Percent | AE4: Max Percent | AF4: Avg. Percent | AG4: Suggested Models | AH4: Min Percent | AI4: Max Percent | AJ4: Avg. Percent | AK4: Suggested Models | AL4: Min Percent | AM4: Max Percent | AN4: Avg. Percent | AO4: Suggested Models | AR4: Model | AS4: Ability to detect | AT4: Ability to be detected
A5: ChatGPT-4o | B5: 90 | C5: 95 | D5: =AVERAGE(B5:C5) -> 92.5 | E5: GPT-4 | F5: 95 | G5: 100 | H5: =AVERAGE(F5:G5) -> 97.5 | I5: GPT-3.5, GPT-4, Gemini | J5: 85 | K5: 90 | L5: =AVERAGE(J5:K5) -> 87.5 | M5: GPT-3.5, GPT-4 | N5: 95 | O5: 100 | P5: =AVERAGE(N5:O5) -> 97.5 | Q5: GPT 3.5, GPT-4, Gemini, Mistral AI | R5: 85 | S5: 90 | T5: =AVERAGE(R5:S5) -> 87.5 | U5: GPT-3.5, GPT-4 | X5: 100 | Y5: GPT-3.5, GPT-4 | AB5: 80 | AC5: BERT, RoBERTa | AF5: 100 | AG5: GPT-3.5, GPT-4 | AH5: 95 | AI5: 100 | AJ5: =AVERAGE(AH5:AI5) -> 97.5 | AK5: GPT-3.5, GPT-4 | AN5: 0 | AO5: NA | AR5: ChatGPT-4o | AS5: =D15 -> 94.25 | AT5: =AVERAGE(D5,H5,L5,T5,X5,AB5,AF5,AJ5,AN5) -> 82.5
A6: Gemini 2.5 Pro | B6: 85 | C6: 95 | D6: =AVERAGE(B6:C6) -> 90 | E6: GPT-4, Claude 3 | F6: 90 | G6: 100 | H6: =AVERAGE(F6:G6) -> 95 | I6: GPT-4, Gemini | J6: 70 | K6: 80 | L6: =AVERAGE(J6:K6) -> 75 | M6: GPT-3.5, GPT-4 | N6: 90 | O6: 100 | P6: =AVERAGE(N6:O6) -> 95 | Q6: GPT 3.5, GPT-4, Gemini, Mistral AI | R6: 80 | S6: 85 | T6: =AVERAGE(R6:S6) -> 82.5 | U6: GPT-3.5, GPT-4 | X6: 100 | Y6: GPT-3.5, GPT-4 | AB6: 90 | AC6: T5, Longformer | AF6: 100 | AG6: GPT-3.5, GPT-4 | AH6: 90 | AI6: 95 | AJ6: =AVERAGE(AH6:AI6) -> 92.5 | AK6: GPT-3.5, GPT-4 | AN6: 0 | AO6: NA | AR6: Gemini 2.5 Pro | AS6: =H15 -> 98.65 | AT6: =AVERAGE(D6,H6,L6,T6,X6,AB6,AF6,AJ6,AN6) -> 80.555556
A7: Claude Sonnet 4 | B7: 95 | C7: 100 | D7: =AVERAGE(B7:C7) -> 97.5 | E7: GPT-4, Claude 3 | F7: 95 | G7: 100 | H7: =AVERAGE(F7:G7) -> 97.5 | I7: GPT-3.5, GPT-4, Gemini | J7: 90 | K7: 95 | L7: =AVERAGE(J7:K7) -> 92.5 | M7: GPT-3.5, GPT-4 | N7: 95 | O7: 100 | P7: =AVERAGE(N7:O7) -> 97.5 | Q7: GPT 3.5, GPT-4, Gemini, Mistral AI | R7: 85 | S7: 90 | T7: =AVERAGE(R7:S7) -> 87.5 | U7: GPT-4 | X7: 100 | Y7: GPT-3.5, GPT-4 | AB7: 85 | AC7: BART, T5 | AF7: 100 | AG7: GPT-3.5, GPT-4 | AJ7: 85 | AK7: GPT-3.5, GPT-4 | AN7: 0 | AO7: NA | AR7: Claude Sonnet 4 | AS7: =L15 -> 85.55 | AT7: =AVERAGE(D7,H7,L7,T7,X7,AB7,AF7,AJ7,AN7) -> 82.777778
A8: Mistral Le Chat | B8: 95 | C8: 100 | D8: =AVERAGE(B8:C8) -> 97.5 | E8: GPT-4, Claude3, Gemini Advanced | F8: 99 | G8: 100 | H8: =AVERAGE(F8:G8) -> 99.5 | I8: GPT-4, Gemini | J8: 95 | K8: 98 | L8: =AVERAGE(J8:K8) -> 96.5 | M8: GPT-3.5, GPT-4 | N8: 98 | O8: 100 | P8: =AVERAGE(N8:O8) -> 99 | Q8: GPT-4, Gemini, Mistral AI | R8: 90 | S8: 95 | T8: =AVERAGE(R8:S8) -> 92.5 | U8: GPT-4 | X8: 100 | Y8: GPT-3.5, GPT-4 | AB8: 95 | AC8: RoBERTa, Longformer | AF8: 100 | AG8: GPT-3.5, GPT-4 | AJ8: 90 | AK8: GPT-4 | AN8: 0 | AO8: NA | AR8: Mistral Le Chat | AS8: =P15 -> 98.3 | AT8: =AVERAGE(D8,H8,L8,T8,X8,AB8,AF8,AJ8,AN8) -> 85.666667
A9: Perplexity | B9: 95 | C9: 100 | D9: =AVERAGE(B9:C9) -> 97.5 | E9: GPT-4, Claude 3 | F9: 95 | G9: 100 | H9: =AVERAGE(F9:G9) -> 97.5 | I9: GPT-3.5, GPT-4, Gemini | J9: 80 | K9: 85 | L9: =AVERAGE(J9:K9) -> 82.5 | M9: GPT-3.5, GPT-4 | N9: 95 | O9: 100 | P9: =AVERAGE(N9:O9) -> 97.5 | Q9: GPT 3.5, GPT-4, Gemini, Mistral AI | R9: 90 | S9: 95 | T9: =AVERAGE(R9:S9) -> 92.5 | U9: GPT-4 | X9: 100 | Y9: GPT-3.5, GPT-4 | AB9: 80 | AC9: BART, T5 | AF9: 100 | AG9: GPT-3.5, GPT-4 | AJ9: 90 | AK9: GPT-4 | AN9: 0 | AO9: NA | AR9: Perplexity | AS9: =T15 -> 90.5 | AT9: =AVERAGE(D9,H9,L9,T9,X9,AB9,AF9,AJ9,AN9) -> 82.222222
A10: DeepSeek V3 | B10: 95 | C10: 100 | D10: =AVERAGE(B10:C10) -> 97.5 | E10: GPT-4, Claude 3 | H10: 100 | I10: GPT-4, Gemini | J10: 95 | K10: 98 | L10: =AVERAGE(J10:K10) -> 96.5 | M10: GPT-3.5, GPT-4 | N10: 99 | O10: 100 | P10: =AVERAGE(N10:O10) -> 99.5 | Q10: GPT-4, Gemini, Mistral AI | R10: 90 | S10: 95 | T10: =AVERAGE(R10:S10) -> 92.5 | U10: GPT-4 | X10: 100 | Y10: GPT-3.5, GPT-4 | AB10: 90 | AC10: BART, T5 | AF10: 100 | AG10: GPT-3.5, GPT-4 | AJ10: 100 | AK10: early versions of GPT | AN10: 5 | AO10: NA | AR10: DeepSeek V3 | AS10: =X15 -> 100 | AT10: =AVERAGE(D10,H10,L10,T10,X10,AB10,AF10,AJ10,AN10) -> 86.833333
A11: Llama-4-Scout-nitro | B11: 90 | C11: 95 | D11: =AVERAGE(B11:C11) -> 92.5 | E11: GPT-4, Claude3, Gemini Advanced | H11: 100 | I11: GPT-4, Gemini | J11: 90 | K11: 95 | L11: =AVERAGE(J11:K11) -> 92.5 | M11: GPT-3.5, GPT-4 | N11: 99 | O11: 100 | P11: =AVERAGE(N11:O11) -> 99.5 | Q11: GPT-4, Gemini, Mistral AI | R11: 90 | S11: 95 | T11: =AVERAGE(R11:S11) -> 92.5 | U11: GPT-4 | X11: 100 | Y11: GPT-3.5, GPT-4 | AB11: 95 | AC11: RoBERTa, Longformer | AF11: 100 | AG11: GPT-3.5, GPT-4 | AJ11: 100 | AK11: GPT-3.5, GPT-4 | AN11: 10 | AO11: NA | AR11: Llama-4-Scout-nitro | AS11: =AB15 -> 87 | AT11: =AVERAGE(D11,H11,L11,T11,X11,AB11,AF11,AJ11,AN11) -> 86.944444
A12: Grok-3 | B12: 90 | C12: 95 | D12: =AVERAGE(B12:C12) -> 92.5 | E12: GPT-4, Claude3, Gemini Advanced | F12: 99 | G12: 100 | H12: =AVERAGE(F12:G12) -> 99.5 | I12: GPT-4, Gemini | J12: 75 | K12: 85 | L12: =AVERAGE(J12:K12) -> 80 | M12: GPT-3.5, GPT-4 | N12: 98 | O12: 100 | P12: =AVERAGE(N12:O12) -> 99 | Q12: GPT-4, Gemini, Mistral AI | R12: 90 | S12: 95 | T12: =AVERAGE(R12:S12) -> 92.5 | U12: GPT-4 | X12: 100 | Y12: GPT-3.5, GPT-4 | AB12: 85 | AC12: BART, T5 | AF12: 100 | AG12: GPT-3.5, GPT-4 | AJ12: 100 | AK12: GPT-3.5, GPT-4 | AN12: 15 | AO12: NA | AR12: Grok-3 | AS12: =AF15 -> 100 | AT12: =AVERAGE(D12,H12,L12,T12,X12,AB12,AF12,AJ12,AN12) -> 84.944444
A13: Qwen3-235b-a22b | B13: 90 | C13: 95 | D13: =AVERAGE(B13:C13) -> 92.5 | E13: GPT-4, Claude 3 | H13: 100 | I13: GPT-4, Gemini | J13: 60 | K13: 70 | L13: =AVERAGE(J13:K13) -> 65 | M13: GPT-4, Claude | N13: 99 | O13: 100 | P13: =AVERAGE(N13:O13) -> 99.5 | Q13: GPT-4, Gemini, Mistral AI | R13: 90 | S13: 95 | T13: =AVERAGE(R13:S13) -> 92.5 | U13: GPT-4 | X13: 100 | Y13: GPT-3.5, GPT-4 | AB13: 90 | AC13: T5, Longformer | AF13: 100 | AG13: GPT-3.5, GPT-4 | AJ13: 100 | AK13: GPT-3.5, GPT-4 | AN13: 12 | AO13: NA | AR13: Qwen3-235b-a22b | AS13: =AJ15 -> 95.5 | AT13: =AVERAGE(D13,H13,L13,T13,X13,AB13,AF13,AJ13,AN13) -> 83.555556
A14: Falcon-H1-3B-Instruct | B14: 90 | C14: 95 | D14: =AVERAGE(B14:C14) -> 92.5 | E14: GPT-4, Claude3, Gemini Advanced | H14: 100 | I14: GPT-4, Gemini | J14: 85 | K14: 90 | L14: =AVERAGE(J14:K14) -> 87.5 | M14: GPT-3.5, GPT-4 | N14: 98 | O14: 100 | P14: =AVERAGE(N14:O14) -> 99 | Q14: GPT-4, Gemini, Mistral AI | R14: 90 | S14: 95 | T14: =AVERAGE(R14:S14) -> 92.5 | U14: GPT-4 | X14: 100 | Y14: GPT-3.5, GPT-4 | AB14: 80 | AC14: BART, T5 | AF14: 100 | AG14: GPT-3.5, GPT-4 | AJ14: 100 | AK14: GPT-3.5, GPT-4 | AN14: 10 | AO14: NA | AR14: Falcon-H1-3B-Instruct | AS14: =AN15 -> 5.2 | AT14: =AVERAGE(D14,H14,L14,T14,X14,AB14,AF14,AJ14,AN14) -> 84.722222
A15: Mean | D15: =AVERAGE(D5:D14) -> 94.25 | H15: =AVERAGE(H5:H14) -> 98.65 | L15: =AVERAGE(L5:L14) -> 85.55 | P15: =AVERAGE(P5:P14) -> 98.3 | T15: =AVERAGE(T5:T14) -> 90.5 | X15: =AVERAGE(X5:X14) -> 100 | AB15: =AVERAGE(AB5:AB14) -> 87 | AF15: =AVERAGE(AF5:AF14) -> 100 | AJ15: =AVERAGE(AJ5:AJ14) -> 95.5 | AN15: =AVERAGE(AN5:AN14) -> 5.2
AR25: Model | AS25: Ability to detect
AR26: Falcon-H1-3B-Instruct | AS26: 5.2
AR27: Claude Sonnet 4 | AS27: 85.55
AR28: Llama-4-Scout-nitro | AS28: 87
AR29: Perplexity | AS29: 90.5
AR30: ChatGPT-4o | AS30: 94.25
AR31: Qwen3-235b-a22b | AS31: 95.5
AR32: Mistral Le Chat | AS32: 98.3
AR33: Gemini 2.5 Pro | AS33: 98.65
AR34: DeepSeek V3 | AS34: 100
AR35: Grok-3 | AS35: 100
AR39: Model | AS39: Ability to be detected
AR40: Gemini 2.5 Pro | AS40: 80.555556
AR41: Perplexity | AS41: 82.222222
AR42: ChatGPT-4o | AS42: 82.5
AR43: Claude Sonnet 4 | AS43: 82.777778
AR44: Qwen3-235b-a22b | AS44: 83.555556
AR45: Falcon-H1-3B-Instruct | AS45: 84.722222
AR46: Grok-3 | AS46: 84.944444
AR47: Mistral Le Chat | AS47: 85.666667
AR48: DeepSeek V3 | AS48: 86.833333
AR49: Llama-4-Scout-nitro | AS49: 86.944444

Sheet Task 8-PI
B2: Detecting Models
